Workbook

Sheet Skill_DataTable
A1: RowName | B1: SkillID | C1: DisplayName_KR | D1: OwnerClass | E1: SkillCategory | F1: SkillType | G1: SkillTier | H1: ActionKind | I1: TargetType | J1: EnergyCost | K1: SkillEnergyCost | L1: BaseValue | M1: ScalingStat | N1: ScalingRatio | O1: HitCount | P1: SecondaryValue | Q1: StatusEffect | R1: StatusValue | S1: StatusDuration | T1: SelfDamage | U1: IconID | V1: AnimMontageTag | W1: VFXTag | X1: SFXTag | Y1: Description_KR | Z1: Notes | AA1: BuyPrice_Dungeon | AB1: SellPrice_Dungeon
A2: fighter_attack | B2: SK_FTR_001 | C2: 공격 태세 | D2: Fighter | E2: Basic | F2: Attack | G2: Surface | H2: HitEnemyMulti | I2: SingleEnemy | J2: 1 | K2: 0 | L2: 3 | M2: ATK | N2: 1 | O2: 2 | P2: 0 | Q2: None | R2: 0 | S2: 0 | T2: 0 | Y2: 기본 공격 자세를 취해 적 1명에게 (3+공격)의 피해를 2회 입힌다. | AA2: =IF(OR(D2="Monster", E2="Basic"), 0, ROUND((MIN(IFERROR(VLOOKUP(G2, Relic_Price_Config!$A$5:$E$9, 4, FALSE), 350), MAX(IFERROR(VLOOKUP(G2, Relic_Price_Config!$A$5:$E$9, 3, FALSE), 210), ROUND((IFERROR(VLOOKUP(H2, Relic_Price_Config!$G$5:$N$100, 4, FALSE), 280) + N(L2) * IF(N(O2)>1, N(O2), 1) * IFERROR(VLOOKUP(H2, Relic_Price_Config!$G$5:$N$100, 5, FALSE), 10) + ABS(N(R2)) * IFERROR(VLOOKUP(H2, Relic_Price_Config!$G$5:$N$100, 6, FALSE), 15) + IF(N(S2)>1, (N(S2)-1)*10, 0)) * IFERROR(VLOOKUP(G2, Relic_Price_Config!$A$5:$E$9, 2, FALSE), 1), 0))) * 0.1) / 5, 0) * 5) -> 0 | AB2: =IF(AA2<=0, 0, ROUND((AA2*0.7)/5, 0)*5) -> 0
A3: fighter_defend | B3: SK_FTR_002 | C3: 방어 태세 | D3: Fighter | E3: Basic | F3: Defense | G3: Surface | H3: ShieldSelf | I3: Self | J3: 1 | K3: 0 | L3: 6 | M3: DEF | N3: 1 | O3: 1 | P3: 0 | Q3: None | R3: 0 | S3: 0 | T3: 0 | Y3: 방어 자세를 굳혀 자신에게 (6+방어)의 보호막을 생성한다. | AA3: =IF(OR(D3="Monster", E3="Basic"), 0, ROUND((MIN(IFERROR(VLOOKUP(G3, Relic_Price_Config!$A$5:$E$9, 4, FALSE), 350), MAX(IFERROR(VLOOKUP(G3, Relic_Price_Config!$A$5:$E$9, 3, FALSE), 210), ROUND((IFERROR(VLOOKUP(H3, Relic_Price_Config!$G$5:$N$100, 4, FALSE), 280) + N(L3) * IF(N(O3)>1, N(O3), 1) * IFERROR(VLOOKUP(H3, Relic_Price_Config!$G$5:$N$100, 5, FALSE), 10) + ABS(N(R3)) * IFERROR(VLOOKUP(H3, Relic_Price_Config!$G$5:$N$100, 6, FALSE), 15) + IF(N(S3)>1, (N(S3)-1)*10, 0)) * IFERROR(VLOOKUP(G3, Relic_Price_Config!$A$5:$E$9, 2, FALSE), 1), 0))) * 0.1) / 5, 0) * 5) -> 0 | AB3: =IF(AA3<=0, 0, ROUND((AA3*0.7)/5, 0)*5) -> 0
A4: fighter_special | B4: SK_FTR_003 | C4: 반격 태세 | D4: Fighter | E4: Basic | F4: Special | G4: Surface | H4: ShieldSelfCounter | I4: Self | J4: 1 | K4: 0 | L4: 3 | M4: DEF | N4: 1 | O4: 1 | P4: 2 | Q4: Counter | R4: 1 | S4: 1 | T4: 0 | Y4: 반격 자세를 취해 자신에게 (3+방어)의 보호막을 생성하고, 1사이클 동안 (2+방어)의 피해를 돌려주는 반격을 부여한다. | Z4: StatusValue=1(반격 스택), StatusDuration=1사이클 SecondaryValue = (반격 기본 데미지) | AA4: =IF(OR(D4="Monster", E4="Basic"), 0, ROUND((MIN(IFERROR(VLOOKUP(G4, Relic_Price_Config!$A$5:$E$9, 4, FALSE), 350), MAX(IFERROR(VLOOKUP(G4, Relic_Price_Config!$A$5:$E$9, 3, FALSE), 210), ROUND((IFERROR(VLOOKUP(H4, Relic_Price_Config!$G$5:$N$100, 4, FALSE), 280) + N(L4) * IF(N(O4)>1, N(O4), 1) * IFERROR(VLOOKUP(H4, Relic_Price_Config!$G$5:$N$100, 5, FALSE), 10) + ABS(N(R4)) * IFERROR(VLOOKUP(H4, Relic_Price_Config!$G$5:$N$100, 6, FALSE), 15) + IF(N(S4)>1, (N(S4)-1)*10, 0)) * IFERROR(VLOOKUP(G4, Relic_Price_Config!$A$5:$E$9, 2, FALSE), 1), 0))) * 0.1) / 5, 0) * 5) -> 0 | AB4: =IF(AA4<=0, 0, ROUND((AA4*0.7)/5, 0)*5) -> 0
A5: engineer_attack | B5: SK_ENG_001 | C5: 마도 캐논 발사 | D5: Engineer | E5: Basic | F5: Attack | G5: Surface | H5: HitEnemySingleAoe | I5: SingleEnemy | J5: 1 | K5: 0 | L5: 5 | M5: ATK | N5: 1 | O5: 1 | P5: 2 | Q5: None | R5: 0 | S5: 0 | T5: 0 | Y5: 마도 캐논을 발사하여 적 1명에게 (5+공격)의 피해를 입히고, 적 전체에게 추가로 (2+공격)의 폭발 피해를 입힌다. | Z5: SecondaryValue=광역 피해 계수(2) | AA5: =IF(OR(D5="Monster", E5="Basic"), 0, ROUND((MIN(IFERROR(VLOOKUP(G5, Relic_Price_Config!$A$5:$E$9, 4, FALSE), 350), MAX(IFERROR(VLOOKUP(G5, Relic_Price_Config!$A$5:$E$9, 3, FALSE), 210), ROUND((IFERROR(VLOOKUP(H5, Relic_Price_Config!$G$5:$N$100, 4, FALSE), 280) + N(L5) * IF(N(O5)>1, N(O5), 1) * IFERROR(VLOOKUP(H5, Relic_Price_Config!$G$5:$N$100, 5, FALSE), 10) + ABS(N(R5)) * IFERROR(VLOOKUP(H5, Relic_Price_Config!$G$5:$N$100, 6, FALSE), 15) + IF(N(S5)>1, (N(S5)-1)*10, 0)) * IFERROR(VLOOKUP(G5, Relic_Price_Config!$A$5:$E$9, 2, FALSE), 1), 0))) * 0.1) / 5, 0) * 5) -> 0 | AB5: =IF(AA5<=0, 0, ROUND((AA5*0.7)/5, 0)*5) -> 0
A6: engineer_defend | B6: SK_ENG_002 | C6: 에너지 쉴드 | D6: Engineer | E6: Basic | F6: Defense | G6: Surface | H6: ShieldSelf | I6: Self | J6: 1 | K6: 0 | L6: 5 | M6: DEF | N6: 1 | O6: 1 | P6: 0 | Q6: None | R6: 0 | S6: 0 | T6: 0 | Y6: 마력 보호막을 전개하여 자신에게 (5+방어)의 보호막을 생성한다. | AA6: =IF(OR(D6="Monster", E6="Basic"), 0, ROUND((MIN(IFERROR(VLOOKUP(G6, Relic_Price_Config!$A$5:$E$9, 4, FALSE), 350), MAX(IFERROR(VLOOKUP(G6, Relic_Price_Config!$A$5:$E$9, 3, FALSE), 210), ROUND((IFERROR(VLOOKUP(H6, Relic_Price_Config!$G$5:$N$100, 4, FALSE), 280) + N(L6) * IF(N(O6)>1, N(O6), 1) * IFERROR(VLOOKUP(H6, Relic_Price_Config!$G$5:$N$100, 5, FALSE), 10) + ABS(N(R6)) * IFERROR(VLOOKUP(H6, Relic_Price_Config!$G$5:$N$100, 6, FALSE), 15) + IF(N(S6)>1, (N(S6)-1)*10, 0)) * IFERROR(VLOOKUP(G6, Relic_Price_Config!$A$5:$E$9, 2, FALSE), 1), 0))) * 0.1) / 5, 0) * 5) -> 0 | AB6: =IF(AA6<=0, 0, ROUND((AA6*0.7)/5, 0)*5) -> 0
A7: engineer_special | B7: SK_ENG_003 | C7: 과부화 | D7: Engineer | E7: Basic | F7: Special | G7: Surface | H7: BraveSelf | I7: Self | J7: 1 | K7: 0 | L7: 0 | N7: 0 | O7: 0 | P7: 0 | Q7: Brave | R7: 1 | S7: 1 | T7: 0 | Y7: 마도 엔진의 출력을 높여 1사이클 동안 자신의 공격을 1 증가시킨다. | AA7: =IF(OR(D7="Monster", E7="Basic"), 0, ROUND((MIN(IFERROR(VLOOKUP(G7, Relic_Price_Config!$A$5:$E$9, 4, FALSE), 350), MAX(IFERROR(VLOOKUP(G7, Relic_Price_Config!$A$5:$E$9, 3, FALSE), 210), ROUND((IFERROR(VLOOKUP(H7, Relic_Price_Config!$G$5:$N$100, 4, FALSE), 280) + N(L7) * IF(N(O7)>1, N(O7), 1) * IFERROR(VLOOKUP(H7, Relic_Price_Config!$G$5:$N$100, 5, FALSE), 10) + ABS(N(R7)) * IFERROR(VLOOKUP(H7, Relic_Price_Config!$G$5:$N$100, 6, FALSE), 15) + IF(N(S7)>1, (N(S7)-1)*10, 0)) * IFERROR(VLOOKUP(G7, Relic_Price_Config!$A$5:$E$9, 2, FALSE), 1), 0))) * 0.1) / 5, 0) * 5) -> 0 | AB7: =IF(AA7<=0, 0, ROUND((AA7*0.7)/5, 0)*5) -> 0
A8: paladin_attack | B8: SK_PAL_001 | C8: 기본 검술 | D8: Paladin | E8: Basic | F8: Attack | G8: Surface | H8: HitEnemy | I8: SingleEnemy | J8: 1 | K8: 0 | L8: 5 | M8: ATK | N8: 1 | O8: 1 | P8: 0 | Q8: None | R8: 0 | S8: 0 | T8: 0 | Y8: 정석적인 검술로 적 1명을 베어 (5+공격)의 피해를 입힌다. | AA8: =IF(OR(D8="Monster", E8="Basic"), 0, ROUND((MIN(IFERROR(VLOOKUP(G8, Relic_Price_Config!$A$5:$E$9, 4, FALSE), 350), MAX(IFERROR(VLOOKUP(G8, Relic_Price_Config!$A$5:$E$9, 3, FALSE), 210), ROUND((IFERROR(VLOOKUP(H8, Relic_Price_Config!$G$5:$N$100, 4, FALSE), 280) + N(L8) * IF(N(O8)>1, N(O8), 1) * IFERROR(VLOOKUP(H8, Relic_Price_Config!$G$5:$N$100, 5, FALSE), 10) + ABS(N(R8)) * IFERROR(VLOOKUP(H8, Relic_Price_Config!$G$5:$N$100, 6, FALSE), 15) + IF(N(S8)>1, (N(S8)-1)*10, 0)) * IFERROR(VLOOKUP(G8, Relic_Price_Config!$A$5:$E$9, 2, FALSE), 1), 0))) * 0.1) / 5, 0) * 5) -> 0 | AB8: =IF(AA8<=0, 0, ROUND((AA8*0.7)/5, 0)*5) -> 0
A9: paladin_defend | B9: SK_PAL_002 | C9: 기본 방패술 | D9: Paladin | E9: Basic | F9: Defense | G9: Surface | H9: ShieldSelf | I9: Self | J9: 1 | K9: 0 | L9: 6 | M9: DEF | N9: 1 | O9: 1 | P9: 0 | Q9: None | R9: 0 | S9: 0 | T9: 0 | Y9: 방패를 앞세워 자신에게 (6+방어)의 보호막을 생성한다. | AA9: =IF(OR(D9="Monster", E9="Basic"), 0, ROUND((MIN(IFERROR(VLOOKUP(G9, Relic_Price_Config!$A$5:$E$9, 4, FALSE), 350), MAX(IFERROR(VLOOKUP(G9, Relic_Price_Config!$A$5:$E$9, 3, FALSE), 210), ROUND((IFERROR(VLOOKUP(H9, Relic_Price_Config!$G$5:$N$100, 4, FALSE), 280) + N(L9) * IF(N(O9)>1, N(O9), 1) * IFERROR(VLOOKUP(H9, Relic_Price_Config!$G$5:$N$100, 5, FALSE), 10) + ABS(N(R9)) * IFERROR(VLOOKUP(H9, Relic_Price_Config!$G$5:$N$100, 6, FALSE), 15) + IF(N(S9)>1, (N(S9)-1)*10, 0)) * IFERROR(VLOOKUP(G9, Relic_Price_Config!$A$5:$E$9, 2, FALSE), 1), 0))) * 0.1) / 5, 0) * 5) -> 0 | AB9: =IF(AA9<=0, 0, ROUND((AA9*0.7)/5, 0)*5) -> 0
A10: paladin_special | B10: SK_PAL_003 | C10: 회복 | D10: Paladin | E10: Basic | F10: Special | G10: Surface | H10: HealAlly | I10: SingleAlly | J10: 1 | K10: 0 | L10: 3 | M10: DEF | N10: 1 | O10: 1 | P10: 0 | Q10: None | R10: 0 | S10: 0 | T10: 0 | Y10: 신성력을 불어넣어 아군 1명의 체력을 (3+방어)만큼 회복한다. | AA10: =IF(OR(D10="Monster", E10="Basic"), 0, ROUND((MIN(IFERROR(VLOOKUP(G10, Relic_Price_Config!$A$5:$E$9, 4, FALSE), 350), MAX(IFERROR(VLOOKUP(G10, Relic_Price_Config!$A$5:$E$9, 3, FALSE), 210), ROUND((IFERROR(VLOOKUP(H10, Relic_Price_Config!$G$5:$N$100, 4, FALSE), 280) + N(L10) * IF(N(O10)>1, N(O10), 1) * IFERROR(VLOOKUP(H10, Relic_Price_Config!$G$5:$N$100, 5, FALSE), 10) + ABS(N(R10)) * IFERROR(VLOOKUP(H10, Relic_Price_Config!$G$5:$N$100, 6, FALSE), 15) + IF(N(S10)>1, (N(S10)-1)*10, 0)) * IFERROR(VLOOKUP(G10, Relic_Price_Config!$A$5:$E$9, 2, FALSE), 1), 0))) * 0.1) / 5, 0) * 5) -> 0 | AB10: =IF(AA10<=0, 0, ROUND((AA10*0.7)/5, 0)*5) -> 0
A11: assassin_attack | B11: SK_ASN_001 | C11: 사혈투 | D11: Assassin | E11: Basic | F11: Attack | G11: Surface | H11: HitEnemyMark | I11: SingleEnemy | J11: 1 | K11: 0 | L11: 5 | M11: ATK | N11: 1 | O11: 1 | P11: 0 | Q11: Mark | R11: 1 | S11: 1 | T11: 0 | Y11: 적 1명의 사혈을 찔러 (5+공격)의 피해를 입히고, 1사이클 동안 급소를 부여한다. | Z11: 기본 공격 무공 (사혈 찌르기) / StatusValue=1(급소 지정 스택), StatusDuration=1사이클 | AA11: =IF(OR(D11="Monster", E11="Basic"), 0, ROUND((MIN(IFERROR(VLOOKUP(G11, Relic_Price_Config!$A$5:$E$9, 4, FALSE), 350), MAX(IFERROR(VLOOKUP(G11, Relic_Price_Config!$A$5:$E$9, 3, FALSE), 210), ROUND((IFERROR(VLOOKUP(H11, Relic_Price_Config!$G$5:$N$100, 4, FALSE), 280) + N(L11) * IF(N(O11)>1, N(O11), 1) * IFERROR(VLOOKUP(H11, Relic_Price_Config!$G$5:$N$100, 5, FALSE), 10) + ABS(N(R11)) * IFERROR(VLOOKUP(H11, Relic_Price_Config!$G$5:$N$100, 6, FALSE), 15) + IF(N(S11)>1, (N(S11)-1)*10, 0)) * IFERROR(VLOOKUP(G11, Relic_Price_Config!$A$5:$E$9, 2, FALSE), 1), 0))) * 0.1) / 5, 0) * 5) -> 0 | AB11: =IF(AA11<=0, 0, ROUND((AA11*0.7)/5, 0)*5) -> 0
A12: assassin_defend | B12: SK_ASN_002 | C12: 은형보 | D12: Assassin | E12: Basic | F12: Defense | G12: Surface | H12: EvasionSelf | I12: Self | J12: 1 | K12: 0 | L12: 0 | M12: DEF | N12: 1 | O12: 3 | P12: 0 | Q12: Evasion | R12: 1 | S12: 3 | T12: 0 | Y12: 그림자 속에 자취를 감춰 3사이클 동안 자신의 회피를 (1+방어)만큼 증가시킨다. | Z12: 기본 방어 신법 (은형술) / StatusDuration=3사이클 | AA12: =IF(OR(D12="Monster", E12="Basic"), 0, ROUND((MIN(IFERROR(VLOOKUP(G12, Relic_Price_Config!$A$5:$E$9, 4, FALSE), 350), MAX(IFERROR(VLOOKUP(G12, Relic_Price_Config!$A$5:$E$9, 3, FALSE), 210), ROUND((IFERROR(VLOOKUP(H12, Relic_Price_Config!$G$5:$N$100, 4, FALSE), 280) + N(L12) * IF(N(O12)>1, N(O12), 1) * IFERROR(VLOOKUP(H12, Relic_Price_Config!$G$5:$N$100, 5, FALSE), 10) + ABS(N(R12)) * IFERROR(VLOOKUP(H12, Relic_Price_Config!$G$5:$N$100, 6, FALSE), 15) + IF(N(S12)>1, (N(S12)-1)*10, 0)) * IFERROR(VLOOKUP(G12, Relic_Price_Config!$A$5:$E$9, 2, FALSE), 1), 0))) * 0.1) / 5, 0) * 5) -> 0 | AB12: =IF(AA12<=0, 0, ROUND((AA12*0.7)/5, 0)*5) -> 0
A13: assassin_special | B13: SK_ASN_003 | C13: 독무탄 | D13: Assassin | E13: Basic | F13: Special | G13: Surface | H13: ShieldSelfPoisonAll | I13: AllEnemies | J13: 1 | K13: 0 | L13: 2 | M13: DEF | N13: 1 | O13: 1 | P13: 0 | Q13: Poison | R13: 2 | S13: 2 | T13: 0 | Y13: 독연막탄을 터뜨려 자신에게 (2+방어)의 보호막을 생성하고, 적 전체에게 2사이클 동안 2의 피해를 입히는 중독을 부여한다. | Z13: 기본 특수 암기 (독연막 살포) / StatusValue=2(중독 스택), StatusDuration=2사이클 | AA13: =IF(OR(D13="Monster", E13="Basic"), 0, ROUND((MIN(IFERROR(VLOOKUP(G13, Relic_Price_Config!$A$5:$E$9, 4, FALSE), 350), MAX(IFERROR(VLOOKUP(G13, Relic_Price_Config!$A$5:$E$9, 3, FALSE), 210), ROUND((IFERROR(VLOOKUP(H13, Relic_Price_Config!$G$5:$N$100, 4, FALSE), 280) + N(L13) * IF(N(O13)>1, N(O13), 1) * IFERROR(VLOOKUP(H13, Relic_Price_Config!$G$5:$N$100, 5, FALSE), 10) + ABS(N(R13)) * IFERROR(VLOOKUP(H13, Relic_Price_Config!$G$5:$N$100, 6, FALSE), 15) + IF(N(S13)>1, (N(S13)-1)*10, 0)) * IFERROR(VLOOKUP(G13, Relic_Price_Config!$A$5:$E$9, 2, FALSE), 1), 0))) * 0.1) / 5, 0) * 5) -> 0 | AB13: =IF(AA13<=0, 0, ROUND((AA13*0.7)/5, 0)*5) -> 0
A14: gale_breathing | B14: SK_CMN_001 | C14: 질풍 호흡 | D14: Fighter | E14: Personal | F14: Special | G14: Surface | H14: BraveSelf | I14: Self | J14: 0 | K14: 1 | L14: 0 | N14: 0 | O14: 1 | P14: 0 | Q14: Brave | R14: 1 | S14: 2 | T14: 0 | Y14: 바람처럼 호흡을 가다듬어 2사이클 동안 자신의 공격을 1 증가시킨다. | Z14: 몬스터 방 처치 보상 풀 (표층 - 질풍신각) | AA14: =IF(OR(D14="Monster", E14="Basic"), 0, ROUND((MIN(IFERROR(VLOOKUP(G14, Relic_Price_Config!$A$5:$E$9, 4, FALSE), 350), MAX(IFERROR(VLOOKUP(G14, Relic_Price_Config!$A$5:$E$9, 3, FALSE), 210), ROUND((IFERROR(VLOOKUP(H14, Relic_Price_Config!$G$5:$N$100, 4, FALSE), 280) + N(L14) * IF(N(O14)>1, N(O14), 1) * IFERROR(VLOOKUP(H14, Relic_Price_Config!$G$5:$N$100, 5, FALSE), 10) + ABS(N(R14)) * IFERROR(VLOOKUP(H14, Relic_Price_Config!$G$5:$N$100, 6, FALSE), 15) + IF(N(S14)>1, (N(S14)-1)*10, 0)) * IFERROR(VLOOKUP(G14, Relic_Price_Config!$A$5:$E$9, 2, FALSE), 1), 0))) * 0.1) / 5, 0) * 5) -> 30 | AB14: =IF(AA14<=0, 0, ROUND((AA14*0.7)/5, 0)*5) -> 20
A15: gale_step | B15: SK_CMN_002 | C15: 질풍보 | D15: Fighter | E15: Personal | F15: Special | G15: Surface | H15: EvasionSelf | I15: Self | J15: 0 | K15: 1 | L15: 0 | N15: 0 | O15: 1 | P15: 0 | Q15: Evasion | R15: 1 | S15: 1 | T15: 0 | Y15: 바람을 타는 보법으로 1사이클 동안 자신의 회피를 1 증가시킨다. | Z15: 몬스터 방 처치 보상 풀 (표층 - 질풍신각) | AA15: =IF(OR(D15="Monster", E15="Basic"), 0, ROUND((MIN(IFERROR(VLOOKUP(G15, Relic_Price_Config!$A$5:$E$9, 4, FALSE), 350), MAX(IFERROR(VLOOKUP(G15, Relic_Price_Config!$A$5:$E$9, 3, FALSE), 210), ROUND((IFERROR(VLOOKUP(H15, Relic_Price_Config!$G$5:$N$100, 4, FALSE), 280) + N(L15) * IF(N(O15)>1, N(O15), 1) * IFERROR(VLOOKUP(H15, Relic_Price_Config!$G$5:$N$100, 5, FALSE), 10) + ABS(N(R15)) * IFERROR(VLOOKUP(H15, Relic_Price_Config!$G$5:$N$100, 6, FALSE), 15) + IF(N(S15)>1, (N(S15)-1)*10, 0)) * IFERROR(VLOOKUP(G15, Relic_Price_Config!$A$5:$E$9, 2, FALSE), 1), 0))) * 0.1) / 5, 0) * 5) -> 30 | AB15: =IF(AA15<=0, 0, ROUND((AA15*0.7)/5, 0)*5) -> 20
A16: gale_triple_kick | B16: SK_CMN_003 | C16: 질풍삼연각 | D16: Fighter | E16: Personal | F16: Attack | G16: Surface | H16: HitEnemyMulti | I16: SingleEnemy | J16: 0 | K16: 1 | L16: 3 | M16: ATK | N16: 1 | O16: 3 | P16: 0 | R16: 0 | S16: 0 | T16: 0 | Y16: 질풍 같은 연속 발차기로 적 1명에게 (3+공격)의 피해를 3회 입힌다. | Z16: 몬스터 방 처치 보상 풀 (표층 - 질풍신각) | AA16: =IF(OR(D16="Monster", E16="Basic"), 0, ROUND((MIN(IFERROR(VLOOKUP(G16, Relic_Price_Config!$A$5:$E$9, 4, FALSE), 350), MAX(IFERROR(VLOOKUP(G16, Relic_Price_Config!$A$5:$E$9, 3, FALSE), 210), ROUND((IFERROR(VLOOKUP(H16, Relic_Price_Config!$G$5:$N$100, 4, FALSE), 280) + N(L16) * IF(N(O16)>1, N(O16), 1) * IFERROR(VLOOKUP(H16, Relic_Price_Config!$G$5:$N$100, 5, FALSE), 10) + ABS(N(R16)) * IFERROR(VLOOKUP(H16, Relic_Price_Config!$G$5:$N$100, 6, FALSE), 15) + IF(N(S16)>1, (N(S16)-1)*10, 0)) * IFERROR(VLOOKUP(G16, Relic_Price_Config!$A$5:$E$9, 2, FALSE), 1), 0))) * 0.1) / 5, 0) * 5) -> 30 | AB16: =IF(AA16<=0, 0, ROUND((AA16*0.7)/5, 0)*5) -> 20
A17: armor_breaker_fist | B17: SK_CMN_004 | C17: 파갑추 | D17: Fighter | E17: Personal | F17: Attack | G17: Surface | H17: HitEnemyLava | I17: SingleEnemy | J17: 0 | K17: 1 | L17: 6 | M17: ATK | N17: 1 | O17: 1 | P17: 0 | Q17: Lava | R17: 1 | S17: 1 | T17: 0 | Y17: 장갑을 꿰뚫는 정권으로 적 1명에게 (6+공격)의 피해를 입히고, 1사이클 동안 방어가 1 하락하는 허점(용암)을 부여한다. | Z17: 몬스터 방 처치 보상 풀 (표층 - 파천금강권) | AA17: =IF(OR(D17="Monster", E17="Basic"), 0, ROUND((MIN(IFERROR(VLOOKUP(G17, Relic_Price_Config!$A$5:$E$9, 4, FALSE), 350), MAX(IFERROR(VLOOKUP(G17, Relic_Price_Config!$A$5:$E$9, 3, FALSE), 210), ROUND((IFERROR(VLOOKUP(H17, Relic_Price_Config!$G$5:$N$100, 4, FALSE), 280) + N(L17) * IF(N(O17)>1, N(O17), 1) * IFERROR(VLOOKUP(H17, Relic_Price_Config!$G$5:$N$100, 5, FALSE), 10) + ABS(N(R17)) * IFERROR(VLOOKUP(H17, Relic_Price_Config!$G$5:$N$100, 6, FALSE), 15) + IF(N(S17)>1, (N(S17)-1)*10, 0)) * IFERROR(VLOOKUP(G17, Relic_Price_Config!$A$5:$E$9, 2, FALSE), 1), 0))) * 0.1) / 5, 0) * 5) -> 30 | AB17: =IF(AA17<=0, 0, ROUND((AA17*0.7)/5, 0)*5) -> 20
A18: iron_shirt_stance | B18: SK_CMN_005 | C18: 철포삼 | D18: Fighter | E18: Personal | F18: Defense | G18: Surface | H18: ShieldSelf | I18: Self | J18: 0 | K18: 1 | L18: 8 | M18: DEF | N18: 1 | O18: 1 | P18: 0 | R18: 0 | S18: 0 | T18: 0 | Y18: 외공으로 피부를 단련하여 자신에게 (8+방어)의 보호막을 생성한다. | Z18: 몬스터 방 처치 보상 풀 (표층 - 파천금강권) | AA18: =IF(OR(D18="Monster", E18="Basic"), 0, ROUND((MIN(IFERROR(VLOOKUP(G18, Relic_Price_Config!$A$5:$E$9, 4, FALSE), 350), MAX(IFERROR(VLOOKUP(G18, Relic_Price_Config!$A$5:$E$9, 3, FALSE), 210), ROUND((IFERROR(VLOOKUP(H18, Relic_Price_Config!$G$5:$N$100, 4, FALSE), 280) + N(L18) * IF(N(O18)>1, N(O18), 1) * IFERROR(VLOOKUP(H18, Relic_Price_Config!$G$5:$N$100, 5, FALSE), 10) + ABS(N(R18)) * IFERROR(VLOOKUP(H18, Relic_Price_Config!$G$5:$N$100, 6, FALSE), 15) + IF(N(S18)>1, (N(S18)-1)*10, 0)) * IFERROR(VLOOKUP(G18, Relic_Price_Config!$A$5:$E$9, 2, FALSE), 1), 0))) * 0.1) / 5, 0) * 5) -> 35 | AB18: =IF(AA18<=0, 0, ROUND((AA18*0.7)/5, 0)*5) -> 25
A19: aura_guard_strike | B19: SK_CMN_006 | C19: 호신강기격 | D19: Fighter | E19: Personal | F19: Attack | G19: Surface | H19: HitEnemyShield | I19: SingleEnemy | J19: 0 | K19: 1 | L19: 6 | M19: ATK | N19: 1 | O19: 1 | P19: 3 | R19: 0 | S19: 0 | T19: 0 | Y19: 공격과 동시에 호신강기를 둘러 적 1명에게 (6+공격)의 피해를 입히고, 자신에게 (3+방어)의 보호막을 생성한다. | Z19: 몬스터 방 처치 보상 풀 (표층 - 파천금강권), SecondaryValue = 획득 보호막 수치 | AA19: =IF(OR(D19="Monster", E19="Basic"), 0, ROUND((MIN(IFERROR(VLOOKUP(G19, Relic_Price_Config!$A$5:$E$9, 4, FALSE), 350), MAX(IFERROR(VLOOKUP(G19, Relic_Price_Config!$A$5:$E$9, 3, FALSE), 210), ROUND((IFERROR(VLOOKUP(H19, Relic_Price_Config!$G$5:$N$100, 4, FALSE), 280) + N(L19) * IF(N(O19)>1, N(O19), 1) * IFERROR(VLOOKUP(H19, Relic_Price_Config!$G$5:$N$100, 5, FALSE), 10) + ABS(N(R19)) * IFERROR(VLOOKUP(H19, Relic_Price_Config!$G$5:$N$100, 6, FALSE), 15) + IF(N(S19)>1, (N(S19)-1)*10, 0)) * IFERROR(VLOOKUP(G19, Relic_Price_Config!$A$5:$E$9, 2, FALSE), 1), 0))) * 0.1) / 5, 0) * 5) -> 30 | AB19: =IF(AA19<=0, 0, ROUND((AA19*0.7)/5, 0)*5) -> 20
A20: dantian_breathing | B20: SK_CMN_007 | C20: 단전 호흡 | D20: Fighter | E20: Personal | F20: Special | G20: Surface | H20: GainEnergy | I20: Self | J20: 0 | K20: 1 | L20: 1 | N20: 0 | O20: 1 | P20: 0 | R20: 0 | S20: 0 | T20: 0 | Y20: 단전의 기운을 끌어올려 즉시 행동 에너지를 1 회복한다. | Z20: 몬스터 방 처치 보상 풀 (표층 - 태극유수권) | AA20: =IF(OR(D20="Monster", E20="Basic"), 0, ROUND((MIN(IFERROR(VLOOKUP(G20, Relic_Price_Config!$A$5:$E$9, 4, FALSE), 350), MAX(IFERROR(VLOOKUP(G20, Relic_Price_Config!$A$5:$E$9, 3, FALSE), 210), ROUND((IFERROR(VLOOKUP(H20, Relic_Price_Config!$G$5:$N$100, 4, FALSE), 280) + N(L20) * IF(N(O20)>1, N(O20), 1) * IFERROR(VLOOKUP(H20, Relic_Price_Config!$G$5:$N$100, 5, FALSE), 10) + ABS(N(R20)) * IFERROR(VLOOKUP(H20, Relic_Price_Config!$G$5:$N$100, 6, FALSE), 15) + IF(N(S20)>1, (N(S20)-1)*10, 0)) * IFERROR(VLOOKUP(G20, Relic_Price_Config!$A$5:$E$9, 2, FALSE), 1), 0))) * 0.1) / 5, 0) * 5) -> 35 | AB20: =IF(AA20<=0, 0, ROUND((AA20*0.7)/5, 0)*5) -> 25
A21: qi_circulation_strike | B21: SK_CMN_008 | C21: 기혈 순환격 | D21: Fighter | E21: Personal | F21: Attack | G21: Surface | H21: HitEnemyHealSelf | I21: SingleEnemy | J21: 0 | K21: 1 | L21: 5 | M21: ATK | N21: 1 | O21: 1 | P21: 3 | R21: 0 | S21: 0 | T21: 0 | Y21: 타격과 함께 기혈을 순환시켜 적 1명에게 (5+공격)의 피해를 입히고, 자신의 체력을 (3+방어)만큼 회복한다. | Z21: 몬스터 방 처치 보상 풀 (표층 - 태극유수권), SecondaryValue = 자가 회복량 | AA21: =IF(OR(D21="Monster", E21="Basic"), 0, ROUND((MIN(IFERROR(VLOOKUP(G21, Relic_Price_Config!$A$5:$E$9, 4, FALSE), 350), MAX(IFERROR(VLOOKUP(G21, Relic_Price_Config!$A$5:$E$9, 3, FALSE), 210), ROUND((IFERROR(VLOOKUP(H21, Relic_Price_Config!$G$5:$N$100, 4, FALSE), 280) + N(L21) * IF(N(O21)>1, N(O21), 1) * IFERROR(VLOOKUP(H21, Relic_Price_Config!$G$5:$N$100, 5, FALSE), 10) + ABS(N(R21)) * IFERROR(VLOOKUP(H21, Relic_Price_Config!$G$5:$N$100, 6, FALSE), 15) + IF(N(S21)>1, (N(S21)-1)*10, 0)) * IFERROR(VLOOKUP(G21, Relic_Price_Config!$A$5:$E$9, 2, FALSE), 1), 0))) * 0.1) / 5, 0) * 5) -> 30 | AB21: =IF(AA21<=0, 0, ROUND((AA21*0.7)/5, 0)*5) -> 20
A22: vitality_qi_flow | B22: SK_CMN_009 | C22: 운기조식 | D22: Fighter | E22: Personal | F22: Defense | G22: Surface | H22: HealSelfProtect | I22: Self | J22: 0 | K22: 1 | L22: 4 | M22: DEF | N22: 1 | O22: 1 | P22: 0 | Q22: Protection | R22: 1 | S22: 1 | T22: 0 | Y22: 내공으로 호흡을 정돈하여 자신의 체력을 (4+방어)만큼 회복하고, 1사이클 동안 방어가 1 증가하는 견고(가호)를 부여한다. | Z22: 몬스터 방 처치 보상 풀 (표층 - 태극유수권) | AA22: =IF(OR(D22="Monster", E22="Basic"), 0, ROUND((MIN(IFERROR(VLOOKUP(G22, Relic_Price_Config!$A$5:$E$9, 4, FALSE), 350), MAX(IFERROR(VLOOKUP(G22, Relic_Price_Config!$A$5:$E$9, 3, FALSE), 210), ROUND((IFERROR(VLOOKUP(H22, Relic_Price_Config!$G$5:$N$100, 4, FALSE), 280) + N(L22) * IF(N(O22)>1, N(O22), 1) * IFERROR(VLOOKUP(H22, Relic_Price_Config!$G$5:$N$100, 5, FALSE), 10) + ABS(N(R22)) * IFERROR(VLOOKUP(H22, Relic_Price_Config!$G$5:$N$100, 6, FALSE), 15) + IF(N(S22)>1, (N(S22)-1)*10, 0)) * IFERROR(VLOOKUP(G22, Relic_Price_Config!$A$5:$E$9, 2, FALSE), 1), 0))) * 0.1) / 5, 0) * 5) -> 30 | AB22: =IF(AA22<=0, 0, ROUND((AA22*0.7)/5, 0)*5) -> 20
A23: flowing_water_parry | B23: SK_CMN_010 | C23: 흘리기 | D23: Fighter | E23: Personal | F23: Defense | G23: Surface | H23: ShieldSelfCounter | I23: Self | J23: 0 | K23: 1 | L23: 5 | M23: DEF | N23: 1 | O23: 1 | P23: 2 | Q23: Counter | R23: 1 | S23: 1 | T23: 0 | Y23: 적의 공격을 흘려낼 준비를 하여 자신에게 (5+방어)의 보호막을 생성하고, 1사이클 동안 (2+방어)의 피해를 돌려주는 반격을 부여한다. | Z23: 몬스터 방 처치 보상 풀 (표층 - 태극유수권), SecondaryValue = 반격 기본 데미지 | AA23: =IF(OR(D23="Monster", E23="Basic"), 0, ROUND((MIN(IFERROR(VLOOKUP(G23, Relic_Price_Config!$A$5:$E$9, 4, FALSE), 350), MAX(IFERROR(VLOOKUP(G23, Relic_Price_Config!$A$5:$E$9, 3, FALSE), 210), ROUND((IFERROR(VLOOKUP(H23, Relic_Price_Config!$G$5:$N$100, 4, FALSE), 280) + N(L23) * IF(N(O23)>1, N(O23), 1) * IFERROR(VLOOKUP(H23, Relic_Price_Config!$G$5:$N$100, 5, FALSE), 10) + ABS(N(R23)) * IFERROR(VLOOKUP(H23, Relic_Price_Config!$G$5:$N$100, 6, FALSE), 15) + IF(N(S23)>1, (N(S23)-1)*10, 0)) * IFERROR(VLOOKUP(G23, Relic_Price_Config!$A$5:$E$9, 2, FALSE), 1), 0))) * 0.1) / 5, 0) * 5) -> 30 | AB23: =IF(AA23<=0, 0, ROUND((AA23*0.7)/5, 0)*5) -> 20
A24: acupoint_pierce | B24: SK_CMN_011 | C24: 혈도 찌르기 | D24: Fighter | E24: Personal | F24: Attack | G24: Surface | H24: HitEnemyMark | I24: SingleEnemy | J24: 0 | K24: 1 | L24: 5 | M24: ATK | N24: 1 | O24: 1 | P24: 0 | Q24: Mark | R24: 1 | S24: 1 | T24: 0 | Y24: 적 1명의 혈도를 정확히 찔러 (5+공격)의 피해를 입히고, 1사이클 동안 급소를 부여한다. | Z24: 몬스터 방 처치 보상 풀 (표층 - 뇌전점혈수) | AA24: =IF(OR(D24="Monster", E24="Basic"), 0, ROUND((MIN(IFERROR(VLOOKUP(G24, Relic_Price_Config!$A$5:$E$9, 4, FALSE), 350), MAX(IFERROR(VLOOKUP(G24, Relic_Price_Config!$A$5:$E$9, 3, FALSE), 210), ROUND((IFERROR(VLOOKUP(H24, Relic_Price_Config!$G$5:$N$100, 4, FALSE), 280) + N(L24) * IF(N(O24)>1, N(O24), 1) * IFERROR(VLOOKUP(H24, Relic_Price_Config!$G$5:$N$100, 5, FALSE), 10) + ABS(N(R24)) * IFERROR(VLOOKUP(H24, Relic_Price_Config!$G$5:$N$100, 6, FALSE), 15) + IF(N(S24)>1, (N(S24)-1)*10, 0)) * IFERROR(VLOOKUP(G24, Relic_Price_Config!$A$5:$E$9, 2, FALSE), 1), 0))) * 0.1) / 5, 0) * 5) -> 30 | AB24: =IF(AA24<=0, 0, ROUND((AA24*0.7)/5, 0)*5) -> 20
A25: thunder_whirlwind_kick | B25: SK_CMN_012 | C25: 뇌전선풍각 | D25: Fighter | E25: Personal | F25: Attack | G25: Surface | H25: HitAllEnemiesMulti | I25: AllEnemies | J25: 0 | K25: 1 | L25: 3 | M25: ATK | N25: 1 | O25: 2 | P25: 0 | R25: 0 | S25: 0 | T25: 0 | Y25: 번개 같은 회전 발차기로 적 전체에게 (3+공격)의 피해를 2회 입힌다. | Z25: 몬스터 방 처치 보상 풀 (표층 - 뇌전점혈수) | AA25: =IF(OR(D25="Monster", E25="Basic"), 0, ROUND((MIN(IFERROR(VLOOKUP(G25, Relic_Price_Config!$A$5:$E$9, 4, FALSE), 350), MAX(IFERROR(VLOOKUP(G25, Relic_Price_Config!$A$5:$E$9, 3, FALSE), 210), ROUND((IFERROR(VLOOKUP(H25, Relic_Price_Config!$G$5:$N$100, 4, FALSE), 280) + N(L25) * IF(N(O25)>1, N(O25), 1) * IFERROR(VLOOKUP(H25, Relic_Price_Config!$G$5:$N$100, 5, FALSE), 10) + ABS(N(R25)) * IFERROR(VLOOKUP(H25, Relic_Price_Config!$G$5:$N$100, 6, FALSE), 15) + IF(N(S25)>1, (N(S25)-1)*10, 0)) * IFERROR(VLOOKUP(G25, Relic_Price_Config!$A$5:$E$9, 2, FALSE), 1), 0))) * 0.1) / 5, 0) * 5) -> 30 | AB25: =IF(AA25<=0, 0, ROUND((AA25*0.7)/5, 0)*5) -> 20
A26: meridian_disrupt | B26: SK_CMN_013 | C26: 경맥 파열 | D26: Fighter | E26: Personal | F26: Attack | G26: Surface | H26: HitEnemyInternalInjury | I26: SingleEnemy | J26: 0 | K26: 1 | L26: 6 | M26: ATK | N26: 1 | O26: 1 | P26: 0 | Q26: InternalInjury | R26: 2 | S26: 1 | T26: 0 | Y26: 적 1명의 경맥에 기운을 침투시켜 (6+공격)의 피해를 입히고, 1사이클 동안 스킬 에너지 사용 시 2 피해를 입는 내상을 부여한다. | Z26: 몬스터 방 처치 보상 풀 (표층 - 뇌전점혈수) | AA26: =IF(OR(D26="Monster", E26="Basic"), 0, ROUND((MIN(IFERROR(VLOOKUP(G26, Relic_Price_Config!$A$5:$E$9, 4, FALSE), 350), MAX(IFERROR(VLOOKUP(G26, Relic_Price_Config!$A$5:$E$9, 3, FALSE), 210), ROUND((IFERROR(VLOOKUP(H26, Relic_Price_Config!$G$5:$N$100, 4, FALSE), 280) + N(L26) * IF(N(O26)>1, N(O26), 1) * IFERROR(VLOOKUP(H26, Relic_Price_Config!$G$5:$N$100, 5, FALSE), 10) + ABS(N(R26)) * IFERROR(VLOOKUP(H26, Relic_Price_Config!$G$5:$N$100, 6, FALSE), 15) + IF(N(S26)>1, (N(S26)-1)*10, 0)) * IFERROR(VLOOKUP(G26, Relic_Price_Config!$A$5:$E$9, 2, FALSE), 1), 0))) * 0.1) / 5, 0) * 5) -> 35 | AB26: =IF(AA26<=0, 0, ROUND((AA26*0.7)/5, 0)*5) -> 25
A27: blood_release | B27: SK_CMN_014 | C27: 혈기 해방 | D27: Fighter | E27: Personal | F27: Special | G27: Surface | H27: BraveSelfDmg | I27: Self | J27: 0 | K27: 1 | L27: 0 | N27: 0 | O27: 1 | P27: 0 | Q27: Brave | R27: 2 | S27: 1 | T27: 2 | Y27: 자신의 체력을 2 소모하여 혈기를 개방하고, 1사이클 동안 자신의 공격을 2 증가시킨다. | Z27: 몬스터 방 처치 보상 풀 (표층 - 혈마광공), SelfDamage=2 | AA27: =IF(OR(D27="Monster", E27="Basic"), 0, ROUND((MIN(IFERROR(VLOOKUP(G27, Relic_Price_Config!$A$5:$E$9, 4, FALSE), 350), MAX(IFERROR(VLOOKUP(G27, Relic_Price_Config!$A$5:$E$9, 3, FALSE), 210), ROUND((IFERROR(VLOOKUP(H27, Relic_Price_Config!$G$5:$N$100, 4, FALSE), 280) + N(L27) * IF(N(O27)>1, N(O27), 1) * IFERROR(VLOOKUP(H27, Relic_Price_Config!$G$5:$N$100, 5, FALSE), 10) + ABS(N(R27)) * IFERROR(VLOOKUP(H27, Relic_Price_Config!$G$5:$N$100, 6, FALSE), 15) + IF(N(S27)>1, (N(S27)-1)*10, 0)) * IFERROR(VLOOKUP(G27, Relic_Price_Config!$A$5:$E$9, 2, FALSE), 1), 0))) * 0.1) / 5, 0) * 5) -> 30 | AB27: =IF(AA27<=0, 0, ROUND((AA27*0.7)/5, 0)*5) -> 20
A28: blood_slash | B28: SK_CMN_015 | C28: 혈참 | D28: Fighter | E28: Personal | F28: Attack | G28: Surface | H28: HitEnemySelfDmgDrain | I28: SingleEnemy | J28: 0 | K28: 1 | L28: 8 | M28: ATK | N28: 1 | O28: 1 | P28: 4 | Q28: SelfDamage | R28: 2 | S28: 0 | T28: 2 | Y28: 자신의 체력을 2 소모하여 적 1명에게 혈기를 실은 (8+공격)의 피해를 입히고, 대상의 체력을 깎았다면 체력을 4 회복한다. | Z28: 몬스터 방 처치 보상 풀 (표층 - 혈마광공), SelfDamage=2, SecondaryValue=체력 타격 성공 시 고정 회복량(4) | AA28: =IF(OR(D28="Monster", E28="Basic"), 0, ROUND((MIN(IFERROR(VLOOKUP(G28, Relic_Price_Config!$A$5:$E$9, 4, FALSE), 350), MAX(IFERROR(VLOOKUP(G28, Relic_Price_Config!$A$5:$E$9, 3, FALSE), 210), ROUND((IFERROR(VLOOKUP(H28, Relic_Price_Config!$G$5:$N$100, 4, FALSE), 280) + N(L28) * IF(N(O28)>1, N(O28), 1) * IFERROR(VLOOKUP(H28, Relic_Price_Config!$G$5:$N$100, 5, FALSE), 10) + ABS(N(R28)) * IFERROR(VLOOKUP(H28, Relic_Price_Config!$G$5:$N$100, 6, FALSE), 15) + IF(N(S28)>1, (N(S28)-1)*10, 0)) * IFERROR(VLOOKUP(G28, Relic_Price_Config!$A$5:$E$9, 2, FALSE), 1), 0))) * 0.1) / 5, 0) * 5) -> 30 | AB28: =IF(AA28<=0, 0, ROUND((AA28*0.7)/5, 0)*5) -> 20
A29: blood_flash | B29: SK_CMN_016 | C29: 혈섬 | D29: Fighter | E29: Personal | F29: Attack | G29: Surface | H29: HitAllSelfDmgDrain | I29: AllEnemies | J29: 0 | K29: 1 | L29: 7 | M29: ATK | N29: 1 | O29: 1 | P29: 2 | Q29: SelfDamage | R29: 3 | S29: 0 | T29: 3 | Y29: 자신의 체력을 3 소모하여 적 전체를 일섬으로 베어 (7+공격)의 피해를 입히고, 체력을 깎은 적 1명당 체력을 2 회복한다. | Z29: 몬스터 방 처치 보상 풀 (표층 - 혈마광공), SelfDamage=3, SecondaryValue=적 1명당 체력 타격 성공 시 고정 회복량(2) | AA29: =IF(OR(D29="Monster", E29="Basic"), 0, ROUND((MIN(IFERROR(VLOOKUP(G29, Relic_Price_Config!$A$5:$E$9, 4, FALSE), 350), MAX(IFERROR(VLOOKUP(G29, Relic_Price_Config!$A$5:$E$9, 3, FALSE), 210), ROUND((IFERROR(VLOOKUP(H29, Relic_Price_Config!$G$5:$N$100, 4, FALSE), 280) + N(L29) * IF(N(O29)>1, N(O29), 1) * IFERROR(VLOOKUP(H29, Relic_Price_Config!$G$5:$N$100, 5, FALSE), 10) + ABS(N(R29)) * IFERROR(VLOOKUP(H29, Relic_Price_Config!$G$5:$N$100, 6, FALSE), 15) + IF(N(S29)>1, (N(S29)-1)*10, 0)) * IFERROR(VLOOKUP(G29, Relic_Price_Config!$A$5:$E$9, 2, FALSE), 1), 0))) * 0.1) / 5, 0) * 5) -> 30 | AB29: =IF(AA29<=0, 0, ROUND((AA29*0.7)/5, 0)*5) -> 20
A30: blood_burst_strike | B30: SK_CMN_017 | C30: 폭혈일격 | D30: Fighter | E30: Personal | F30: Attack | G30: Surface | H30: HitEnemySelfDmgDrain | I30: SingleEnemy | J30: 0 | K30: 1 | L30: 12 | M30: ATK | N30: 1 | O30: 1 | P30: 6 | Q30: SelfDamage | R30: 4 | S30: 0 | T30: 4 | Y30: 자신의 체력을 4 소모하여 혈기를 폭발시키는 일격으로 적 1명에게 (12+공격)의 피해를 입히고, 대상의 체력을 깎았다면 체력을 6 회복한다. | Z30: 몬스터 방 처치 보상 풀 (표층 - 혈마광공), SelfDamage=4, SecondaryValue=체력 타격 성공 시 고정 회복량(6) | AA30: =IF(OR(D30="Monster", E30="Basic"), 0, ROUND((MIN(IFERROR(VLOOKUP(G30, Relic_Price_Config!$A$5:$E$9, 4, FALSE), 350), MAX(IFERROR(VLOOKUP(G30, Relic_Price_Config!$A$5:$E$9, 3, FALSE), 210), ROUND((IFERROR(VLOOKUP(H30, Relic_Price_Config!$G$5:$N$100, 4, FALSE), 280) + N(L30) * IF(N(O30)>1, N(O30), 1) * IFERROR(VLOOKUP(H30, Relic_Price_Config!$G$5:$N$100, 5, FALSE), 10) + ABS(N(R30)) * IFERROR(VLOOKUP(H30, Relic_Price_Config!$G$5:$N$100, 6, FALSE), 15) + IF(N(S30)>1, (N(S30)-1)*10, 0)) * IFERROR(VLOOKUP(G30, Relic_Price_Config!$A$5:$E$9, 2, FALSE), 1), 0))) * 0.1) / 5, 0) * 5) -> 30 | AB30: =IF(AA30<=0, 0, ROUND((AA30*0.7)/5, 0)*5) -> 20
A31: storm_fighting_spirit | B31: SK_CMN_018 | C31: 폭풍같은 투기 | D31: Fighter | E31: Personal | F31: Special | G31: Mid | H31: BraveSelf | I31: Self | J31: 0 | K31: 1 | L31: 0 | N31: 0 | O31: 1 | P31: 0 | Q31: Brave | R31: 2 | S31: 2 | T31: 0 | Y31: 폭풍처럼 휘몰아치는 투기를 일으켜 2사이클 동안 자신의 공격을 2 증가시킨다. | Z31: 몬스터 방 처치 보상 풀 (중층 - 질풍신각) | AA31: =IF(OR(D31="Monster", E31="Basic"), 0, ROUND((MIN(IFERROR(VLOOKUP(G31, Relic_Price_Config!$A$5:$E$9, 4, FALSE), 350), MAX(IFERROR(VLOOKUP(G31, Relic_Price_Config!$A$5:$E$9, 3, FALSE), 210), ROUND((IFERROR(VLOOKUP(H31, Relic_Price_Config!$G$5:$N$100, 4, FALSE), 280) + N(L31) * IF(N(O31)>1, N(O31), 1) * IFERROR(VLOOKUP(H31, Relic_Price_Config!$G$5:$N$100, 5, FALSE), 10) + ABS(N(R31)) * IFERROR(VLOOKUP(H31, Relic_Price_Config!$G$5:$N$100, 6, FALSE), 15) + IF(N(S31)>1, (N(S31)-1)*10, 0)) * IFERROR(VLOOKUP(G31, Relic_Price_Config!$A$5:$E$9, 2, FALSE), 1), 0))) * 0.1) / 5, 0) * 5) -> 50 | AB31: =IF(AA31<=0, 0, ROUND((AA31*0.7)/5, 0)*5) -> 35
A32: sky_walk_step | B32: SK_CMN_019 | C32: 허공답보 | D32: Fighter | E32: Personal | F32: Defense | G32: Mid | H32: ShieldSelfEvasion | I32: Self | J32: 0 | K32: 1 | L32: 9 | M32: DEF | N32: 1 | O32: 1 | P32: 0 | Q32: Evasion | R32: 2 | S32: 1 | T32: 0 | Y32: 허공을 밟는 보법으로 자신에게 (9+방어)의 보호막을 생성하고, 1사이클 동안 회피가 2 증가하는 민첩을 부여한다. | Z32: 몬스터 방 처치 보상 풀 (중층 - 질풍신각) | AA32: =IF(OR(D32="Monster", E32="Basic"), 0, ROUND((MIN(IFERROR(VLOOKUP(G32, Relic_Price_Config!$A$5:$E$9, 4, FALSE), 350), MAX(IFERROR(VLOOKUP(G32, Relic_Price_Config!$A$5:$E$9, 3, FALSE), 210), ROUND((IFERROR(VLOOKUP(H32, Relic_Price_Config!$G$5:$N$100, 4, FALSE), 280) + N(L32) * IF(N(O32)>1, N(O32), 1) * IFERROR(VLOOKUP(H32, Relic_Price_Config!$G$5:$N$100, 5, FALSE), 10) + ABS(N(R32)) * IFERROR(VLOOKUP(H32, Relic_Price_Config!$G$5:$N$100, 6, FALSE), 15) + IF(N(S32)>1, (N(S32)-1)*10, 0)) * IFERROR(VLOOKUP(G32, Relic_Price_Config!$A$5:$E$9, 2, FALSE), 1), 0))) * 0.1) / 5, 0) * 5) -> 50 | AB32: =IF(AA32<=0, 0, ROUND((AA32*0.7)/5, 0)*5) -> 35
A33: storm_quad_kick | B33: SK_CMN_020 | C33: 폭풍사연각 | D33: Fighter | E33: Personal | F33: Attack | G33: Mid | H33: HitEnemyMulti | I33: SingleEnemy | J33: 0 | K33: 1 | L33: 4 | M33: ATK | N33: 1 | O33: 4 | P33: 0 | R33: 0 | S33: 0 | T33: 0 | Y33: 폭풍처럼 몰아치는 4연속 발차기로 적 1명에게 (4+공격)의 피해를 4회 입힌다. | Z33: 몬스터 방 처치 보상 풀 (중층 - 질풍신각) | AA33: =IF(OR(D33="Monster", E33="Basic"), 0, ROUND((MIN(IFERROR(VLOOKUP(G33, Relic_Price_Config!$A$5:$E$9, 4, FALSE), 350), MAX(IFERROR(VLOOKUP(G33, Relic_Price_Config!$A$5:$E$9, 3, FALSE), 210), ROUND((IFERROR(VLOOKUP(H33, Relic_Price_Config!$G$5:$N$100, 4, FALSE), 280) + N(L33) * IF(N(O33)>1, N(O33), 1) * IFERROR(VLOOKUP(H33, Relic_Price_Config!$G$5:$N$100, 5, FALSE), 10) + ABS(N(R33)) * IFERROR(VLOOKUP(H33, Relic_Price_Config!$G$5:$N$100, 6, FALSE), 15) + IF(N(S33)>1, (N(S33)-1)*10, 0)) * IFERROR(VLOOKUP(G33, Relic_Price_Config!$A$5:$E$9, 2, FALSE), 1), 0))) * 0.1) / 5, 0) * 5) -> 55 | AB33: =IF(AA33<=0, 0, ROUND((AA33*0.7)/5, 0)*5) -> 40
A34: bone_crushing_strike | B34: SK_CMN_021 | C34: 쇄골파천 | D34: Fighter | E34: Personal | F34: Attack | G34: Mid | H34: HitEnemyLava | I34: SingleEnemy | J34: 0 | K34: 1 | L34: 12 | M34: ATK | N34: 1 | O34: 1 | P34: 0 | Q34: Lava | R34: 2 | S34: 2 | T34: 0 | Y34: 뼈를 부수는 일격으로 적 1명에게 (12+공격)의 피해를 입히고, 2사이클 동안 방어가 2 하락하는 허점(용암)을 부여한다. | Z34: 몬스터 방 처치 보상 풀 (중층 - 파천금강권) | AA34: =IF(OR(D34="Monster", E34="Basic"), 0, ROUND((MIN(IFERROR(VLOOKUP(G34, Relic_Price_Config!$A$5:$E$9, 4, FALSE), 350), MAX(IFERROR(VLOOKUP(G34, Relic_Price_Config!$A$5:$E$9, 3, FALSE), 210), ROUND((IFERROR(VLOOKUP(H34, Relic_Price_Config!$G$5:$N$100, 4, FALSE), 280) + N(L34) * IF(N(O34)>1, N(O34), 1) * IFERROR(VLOOKUP(H34, Relic_Price_Config!$G$5:$N$100, 5, FALSE), 10) + ABS(N(R34)) * IFERROR(VLOOKUP(H34, Relic_Price_Config!$G$5:$N$100, 6, FALSE), 15) + IF(N(S34)>1, (N(S34)-1)*10, 0)) * IFERROR(VLOOKUP(G34, Relic_Price_Config!$A$5:$E$9, 2, FALSE), 1), 0))) * 0.1) / 5, 0) * 5) -> 55 | AB34: =IF(AA34<=0, 0, ROUND((AA34*0.7)/5, 0)*5) -> 40
A35: diamond_body_stance | B35: SK_CMN_022 | C35: 금강불괴 | D35: Fighter | E35: Personal | F35: Defense | G35: Mid | H35: ShieldSelfSolid | I35: Self | J35: 0 | K35: 1 | L35: 14 | M35: DEF | N35: 1 | O35: 1 | P35: 0 | Q35: Solid | R35: 2 | S35: 2 | T35: 0 | Y35: 금강석처럼 육체를 경화시켜 자신에게 (14+방어)의 보호막을 생성하고, 2사이클 동안 방어를 2 증가시킨다. | Z35: 몬스터 방 처치 보상 풀 (중층 - 파천금강권) | AA35: =IF(OR(D35="Monster", E35="Basic"), 0, ROUND((MIN(IFERROR(VLOOKUP(G35, Relic_Price_Config!$A$5:$E$9, 4, FALSE), 350), MAX(IFERROR(VLOOKUP(G35, Relic_Price_Config!$A$5:$E$9, 3, FALSE), 210), ROUND((IFERROR(VLOOKUP(H35, Relic_Price_Config!$G$5:$N$100, 4, FALSE), 280) + N(L35) * IF(N(O35)>1, N(O35), 1) * IFERROR(VLOOKUP(H35, Relic_Price_Config!$G$5:$N$100, 5, FALSE), 10) + ABS(N(R35)) * IFERROR(VLOOKUP(H35, Relic_Price_Config!$G$5:$N$100, 6, FALSE), 15) + IF(N(S35)>1, (N(S35)-1)*10, 0)) * IFERROR(VLOOKUP(G35, Relic_Price_Config!$A$5:$E$9, 2, FALSE), 1), 0))) * 0.1) / 5, 0) * 5) -> 55 | AB35: =IF(AA35<=0, 0, ROUND((AA35*0.7)/5, 0)*5) -> 40
A36: vajra_shatter_fist | B36: SK_CMN_023 | C36: 금강파쇄권 | D36: Fighter | E36: Personal | F36: Attack | G36: Mid | H36: HitEnemyShield | I36: SingleEnemy | J36: 0 | K36: 1 | L36: 11 | M36: ATK | N36: 1 | O36: 1 | P36: 7 | R36: 0 | S36: 0 | T36: 0 | Y36: 강기를 두른 주먹으로 적 1명에게 (11+공격)의 피해를 입히고, 자신에게 (7+방어)의 보호막을 생성한다. | Z36: 몬스터 방 처치 보상 풀 (중층 - 파천금강권), SecondaryValue = 획득 보호막 수치 | AA36: =IF(OR(D36="Monster", E36="Basic"), 0, ROUND((MIN(IFERROR(VLOOKUP(G36, Relic_Price_Config!$A$5:$E$9, 4, FALSE), 350), MAX(IFERROR(VLOOKUP(G36, Relic_Price_Config!$A$5:$E$9, 3, FALSE), 210), ROUND((IFERROR(VLOOKUP(H36, Relic_Price_Config!$G$5:$N$100, 4, FALSE), 280) + N(L36) * IF(N(O36)>1, N(O36), 1) * IFERROR(VLOOKUP(H36, Relic_Price_Config!$G$5:$N$100, 5, FALSE), 10) + ABS(N(R36)) * IFERROR(VLOOKUP(H36, Relic_Price_Config!$G$5:$N$100, 6, FALSE), 15) + IF(N(S36)>1, (N(S36)-1)*10, 0)) * IFERROR(VLOOKUP(G36, Relic_Price_Config!$A$5:$E$9, 2, FALSE), 1), 0))) * 0.1) / 5, 0) * 5) -> 50 | AB36: =IF(AA36<=0, 0, ROUND((AA36*0.7)/5, 0)*5) -> 35
A37: meridian_unlock | B37: SK_CMN_024 | C37: 기맥 개방 | D37: Fighter | E37: Personal | F37: Special | G37: Mid | H37: GainEnergyProtectSelf | I37: Self | J37: 0 | K37: 1 | L37: 1 | N37: 0 | O37: 1 | P37: 0 | Q37: Protection | R37: 1 | S37: 2 | T37: 0 | Y37: 전신의 기맥을 개방하여 즉시 행동 에너지를 1 회복하고, 2사이클 동안 방어가 1 증가하는 견고(가호)를 부여한다. | Z37: 몬스터 방 처치 보상 풀 (중층 - 태극유수권) | AA37: =IF(OR(D37="Monster", E37="Basic"), 0, ROUND((MIN(IFERROR(VLOOKUP(G37, Relic_Price_Config!$A$5:$E$9, 4, FALSE), 350), MAX(IFERROR(VLOOKUP(G37, Relic_Price_Config!$A$5:$E$9, 3, FALSE), 210), ROUND((IFERROR(VLOOKUP(H37, Relic_Price_Config!$G$5:$N$100, 4, FALSE), 280) + N(L37) * IF(N(O37)>1, N(O37), 1) * IFERROR(VLOOKUP(H37, Relic_Price_Config!$G$5:$N$100, 5, FALSE), 10) + ABS(N(R37)) * IFERROR(VLOOKUP(H37, Relic_Price_Config!$G$5:$N$100, 6, FALSE), 15) + IF(N(S37)>1, (N(S37)-1)*10, 0)) * IFERROR(VLOOKUP(G37, Relic_Price_Config!$A$5:$E$9, 2, FALSE), 1), 0))) * 0.1) / 5, 0) * 5) -> 50 | AB37: =IF(AA37<=0, 0, ROUND((AA37*0.7)/5, 0)*5) -> 35
A38: taiji_revival_fist | B38: SK_CMN_025 | C38: 태극회생권 | D38: Fighter | E38: Personal | F38: Attack | G38: Mid | H38: HitEnemyHealSelf | I38: SingleEnemy | J38: 0 | K38: 1 | L38: 10 | M38: ATK | N38: 1 | O38: 1 | P38: 6 | R38: 0 | S38: 0 | T38: 0 | Y38: 태극의 순환지기로 적 1명에게 (10+공격)의 피해를 입히고, 자신의 체력을 (6+방어)만큼 회복한다. | Z38: 몬스터 방 처치 보상 풀 (중층 - 태극유수권), SecondaryValue = 자가 회복량 | AA38: =IF(OR(D38="Monster", E38="Basic"), 0, ROUND((MIN(IFERROR(VLOOKUP(G38, Relic_Price_Config!$A$5:$E$9, 4, FALSE), 350), MAX(IFERROR(VLOOKUP(G38, Relic_Price_Config!$A$5:$E$9, 3, FALSE), 210), ROUND((IFERROR(VLOOKUP(H38, Relic_Price_Config!$G$5:$N$100, 4, FALSE), 280) + N(L38) * IF(N(O38)>1, N(O38), 1) * IFERROR(VLOOKUP(H38, Relic_Price_Config!$G$5:$N$100, 5, FALSE), 10) + ABS(N(R38)) * IFERROR(VLOOKUP(H38, Relic_Price_Config!$G$5:$N$100, 6, FALSE), 15) + IF(N(S38)>1, (N(S38)-1)*10, 0)) * IFERROR(VLOOKUP(G38, Relic_Price_Config!$A$5:$E$9, 2, FALSE), 1), 0))) * 0.1) / 5, 0) * 5) -> 50 | AB38: =IF(AA38<=0, 0, ROUND((AA38*0.7)/5, 0)*5) -> 35
A39: taiji_qi_barrier | B39: SK_CMN_026 | C39: 태극기공 | D39: Fighter | E39: Personal | F39: Defense | G39: Mid | H39: ShieldSelfAbsorption | I39: Self | J39: 0 | K39: 1 | L39: 11 | M39: DEF | N39: 1 | O39: 1 | P39: 0 | Q39: Absorption | R39: 20 | S39: 1 | T39: 0 | Y39: 부드러운 태극 기공을 펼쳐 자신에게 (11+방어)의 보호막을 생성하고, 1사이클 동안 피격 시 받은 피해의 20%를 회복하는 흡수를 부여한다. | Z39: 몬스터 방 처치 보상 풀 (중층 - 태극유수권) | AA39: =IF(OR(D39="Monster", E39="Basic"), 0, ROUND((MIN(IFERROR(VLOOKUP(G39, Relic_Price_Config!$A$5:$E$9, 4, FALSE), 350), MAX(IFERROR(VLOOKUP(G39, Relic_Price_Config!$A$5:$E$9, 3, FALSE), 210), ROUND((IFERROR(VLOOKUP(H39, Relic_Price_Config!$G$5:$N$100, 4, FALSE), 280) + N(L39) * IF(N(O39)>1, N(O39), 1) * IFERROR(VLOOKUP(H39, Relic_Price_Config!$G$5:$N$100, 5, FALSE), 10) + ABS(N(R39)) * IFERROR(VLOOKUP(H39, Relic_Price_Config!$G$5:$N$100, 6, FALSE), 15) + IF(N(S39)>1, (N(S39)-1)*10, 0)) * IFERROR(VLOOKUP(G39, Relic_Price_Config!$A$5:$E$9, 2, FALSE), 1), 0))) * 0.1) / 5, 0) * 5) -> 55 | AB39: =IF(AA39<=0, 0, ROUND((AA39*0.7)/5, 0)*5) -> 40
A40: taiji_counter_formation | B40: SK_CMN_027 | C40: 태극반격진 | D40: Fighter | E40: Personal | F40: Defense | G40: Mid | H40: ShieldSelfCounter | I40: Self | J40: 0 | K40: 1 | L40: 11 | M40: DEF | N40: 1 | O40: 1 | P40: 4 | Q40: Counter | R40: 1 | S40: 1 | T40: 0 | Y40: 태극 반격진을 펼쳐 자신에게 (11+방어)의 보호막을 생성하고, 1사이클 동안 (4+방어)의 피해를 돌려주는 반격을 부여한다. | Z40: 몬스터 방 처치 보상 풀 (중층 - 태극유수권), SecondaryValue = 반격 기본 데미지 | AA40: =IF(OR(D40="Monster", E40="Basic"), 0, ROUND((MIN(IFERROR(VLOOKUP(G40, Relic_Price_Config!$A$5:$E$9, 4, FALSE), 350), MAX(IFERROR(VLOOKUP(G40, Relic_Price_Config!$A$5:$E$9, 3, FALSE), 210), ROUND((IFERROR(VLOOKUP(H40, Relic_Price_Config!$G$5:$N$100, 4, FALSE), 280) + N(L40) * IF(N(O40)>1, N(O40), 1) * IFERROR(VLOOKUP(H40, Relic_Price_Config!$G$5:$N$100, 5, FALSE), 10) + ABS(N(R40)) * IFERROR(VLOOKUP(H40, Relic_Price_Config!$G$5:$N$100, 6, FALSE), 15) + IF(N(S40)>1, (N(S40)-1)*10, 0)) * IFERROR(VLOOKUP(G40, Relic_Price_Config!$A$5:$E$9, 2, FALSE), 1), 0))) * 0.1) / 5, 0) * 5) -> 55 | AB40: =IF(AA40<=0, 0, ROUND((AA40*0.7)/5, 0)*5) -> 40
...

Sheet Field_Guide
A1: 스킬 데이터 필드 가이드
A2: Skill_DataTable 시트의 각 컬럼(변수) 설명. 언리얼 FTableRowBase 구조체 필드로 그대로 매핑 가능하도록 설계함.
A4: Field(변수명) | B4: DataType | C4: 설명 | D4: 허용 값 / 예시
A5: RowName | B5: Name(FName) | C5: 언리얼 DataTable의 고유 행 이름. 다른 테이블에서 참조하는 키. | D5: 예: monk_attack (영문 소문자+언더바 권장)
A6: SkillID | B6: FString | C6: 기획/기획서 추적용 스킬 고유 코드. | D6: 예: SK_MONK_001
A7: DisplayName_KR | B7: FText | C7: UI에 표시될 한글 스킬명. | D7: 예: 공격 태세
A8: OwnerClass | B8: Enum(ECharClass) | C8: 이 스킬을 보유한 캐릭터 클래스. 공용 스킬은 Common. | D8: Monk / Engineer / Paladin / Assassin / Common
A9: SkillCategory | B9: Enum(ESkillCategory) | C9: PDF 기준 스킬 분류. | D9: Basic(기본) / Common(공용) / Personal(개인)
A10: SkillType | B10: Enum(ESkillType) | C10: 스킬 분류 — 행동형인지 특수형인지. | D10: Attack(공격) / Defense(방어) / Special(특수)
A11: SkillTier | B11: Enum(ESkillTier) | C11: PDF 기준 획득 가능 층 등급(별 색상). | D11: Surface(표층/회색) / Mid(중층/노랑) / Deep(심층/빨강)
A12: ActionKind | B12: Enum(EActionKind) | C12: 실제 효과 실행 로직 종류. Enum_Reference 시트 참고. | D12: 예: HitEnemy, ShieldSelf, HealAlly 등 20종
A13: TargetType | B13: Enum(ETargetType) | C13: 스킬의 대상 지정 방식. | D13: Self / SingleEnemy / AllEnemies / SingleAlly / AllAllies
A14: EnergyCost | B14: int32 | C14: 기본 행동 에너지 소모량(매 턴 3까지 회복). | D14: 보통 1
A15: SkillEnergyCost | B15: int32 | C15: 강화 에너지(획득 스킬 전용 자원) 소모량. 기본 스킬은 0. | D15: 보통 0(기본) 또는 1(공용/개인)
... A32: SellPrice_Dungeon | B32: int32 | C32: 던전 상점 등에서 스킬 판매 시 얻는 던전 재화 가격 (던전 구매가의 70%, 5단위 반올림). | D32: 예: 표층 20~25 / 중층 35~40 / 심층 45~50
A37: 기타 Enum | B37: 값 목록
A38: OwnerClass | B38: Monk, Engineer, Paladin, Assassin, Common
A39: SkillCategory | B39: Basic, Common, Personal
A40: SkillType | B40: Attack, Defense, Special
A41: SkillTier | B41: Surface, Mid, Deep
A42: TargetType | B42: Self, SingleEnemy, AllEnemies, SingleAlly, AllAllies
A43: ScalingStat | B43: ATK, DEF, None
A44: StatusEffect | B44: None, Poison, Mark, EvasionBuff, Counter, SelfDamage

Sheet Enum_Reference
A1: Enum 값 레퍼런스
A2: ActionKind에 새 스킬을 추가할 때 사용할 수 있는 실행 로직 종류와 각 로직이 어떤 변수를 쓰는지 정리.
A4: ActionKind | B4: 설명 | C4: 사용하는 주요 필드 | D4: TargetType 예시 | E4: 참조 ActionKind | F4: 비고 | H4: OwnerClass | I4: SkillCategory | J4: SkillType | K4: SkillTier | L4: StatusEffect | M4: TargetType | N4: RelicTier
A5: HitEnemy | B5: 적 1명에게 단일 피해 | C5: BaseValue, ScalingStat | D5: SingleEnemy | F5: 가장 기본적인 단일 공격 | H5: Fighter | I5: Basic | J5: Attack | K5: Mid | L5: None | M5: Self | N5: Mid
A6: HitEnemyMulti | B6: 적 1명에게 다단 피해 | C6: BaseValue, HitCount, ScalingStat | D6: SingleEnemy | E6: HitEnemy * HitCount | F6: 타수만큼 반복 적용 | H6: Engineer | I6: Common | J6: Defense | K6: Deep | L6: Counter | M6: SingleEnemy | N6: Deep
A7: HitEnemySingleAoe | B7: 적 1명 주 피해 + 전체 적 광역 피해 | C7: BaseValue(주피해), SecondaryValue(광역) | D7: SingleEnemy | E7: HitEnemy + HitAllEnemies | F7: 선택 대상은 주 피해만, 광역은 자동으로 전체 적 | H7: Paladin | I7: Personal | J7: Special | K7: Surface | L7: Mark | M7: AllEnemies | N7: Surface
A8: HitAllEnemies | B8: 전체 적에게 동일 피해 | C8: BaseValue, ScalingStat | D8: AllEnemies | F8: 대상 선택 불필요 | H8: Assassin | I8: Event | L8: Evasion | M8: SingleAlly | N8: Basic
A9: StatusMark | B9: 적 1명에게 급소 부여 | C9: StatusEffect=Mark, StatusValue, StatusDuration | D9: SingleEnemy | F9: 선택한 대상에게 표식(급소 지정 버프) | H9: Shared | L9: Poison | M9: AllAllies | N9: Upgrade
A10: StatusPoison | B10: 적 1명에게 중독 부여 | C10: StatusEffect=Poison, StatusValue, StatusDuration | D10: SingleEnemy | F10: 선택한 대상에게 중독 부여 | H10: Monster | L10: SelfDamage
A11: HitEnemyMark | B11: 적 1명 피해 + 급소 부여 | C11: BaseValue, StatusEffect=Mark, StatusValue, StatusDuration | D11: SingleEnemy | E11: HitEnemy + StatusMark | F11: 표식 대상은 추가 피해 등 후속 효과 확장 가능 | H11: Event | L11: Brave
A12: HitEnemyPoison | B12: 적 1명 피해 + 중독 부여 | C12: BaseValue, StatusEffect=Poison, StatusValue, StatusDuration | D12: SingleEnemy | E12: HitEnemy + StatusPoison | F12: 매 사이클 종료 시 중독 수치만큼 도트 피해 | H12: Quest | L12: Protection
A13: DmgSelf | B13: 시전자 반동 피해 | C13: SelfDamage | D13: Self | F13: 자체 뎀 | L13: Ice
A14: HitEnemySelfDmg | B14: 적 1명 피해 + 시전자 반동 피해 | C14: BaseValue, SelfDamage | D14: SingleEnemy | E14: HitEnemy + DmgSelf | F14: 고위험 고보상 스킬 | L14: Lava
A15: ShieldSelf | B15: 자신에게 보호막 생성 | C15: BaseValue, ScalingStat | D15: Self | L15: Metal
A16: CounterSelf | B16: 자신 반격 부여 | C16: BaseValue, StatusEffect=Counter, StatusDuration, SecondaryValue | D16: Self | F16: 반격 상태 동안 피격 시 자동 반격, SecoundaryValue 만큼의 데미지 부여 | L16: Acid
A17: ShieldSelfCounter | B17: 자신 보호막 + 반격 부여 | C17: BaseValue, StatusEffect=Counter, StatusDuration | D17: Self | E17: ShieldSelf + CounterSelf | F17: 반격 상태 동안 피격 시 자동 반격 | L17: Fear
A18: ShieldAll | B18: 아군 전체에게 보호막 생성 | C18: BaseValue, ScalingStat | D18: AllAllies | L18: Fusion
A19: HealAlly | B19: 아군 1명 회복 | C19: BaseValue, ScalingStat | D19: SingleAlly | L19: Indomitable
A20: HealAll | B20: 아군 전체 회복 | C20: BaseValue, ScalingStat | D20: AllAllies | L20: Solid
A21: EvasionSelf | B21: 자신 회피 수치 증가(사이클 한정) | C21: StatusEffect=Evasion, StatusValue, StatusDuration | D21: Self | F21: 1사이클 동안 회피를 StatusValue만큼 증가시킨다. | L21: IronWall
A22: StatusPoisonAll | B22: 전체 적 중독 부여 | C22: StatusEffect=Poison, StatusValue, StatusDuration | D22: AllEnemies | L22: Absorption
A23: EvasionSelfPoisonAll | B23: 자신 회피 증가 + 전체 적 중독 부여 | C23: BaseValue, StatusEffect=Poison, StatusValue, StatusDuration | D23: AllEnemies | E23: EvasionSelf + PoisonAll | F23: 자신 회피 증가 후 전체 적에게 중독 부여 | L23: InternalInjury
A24: GainEnergy | B24: 즉시 행동 에너지 회복 | C24: BaseValue, ScalingStat | D24: Self | F24: 즉시 발동, 소모 자원 회복형 스킬 | L24: Reflux
A25: BraveSelf | B25: 자신에게 용기 부여 | C25: StatusEffect=Brave, StatusValue, StatusDuration | D25: Self | F25: 자신의 공격력을 StatusValue만큼 증가 | L25: Vitality
A26: BraveAll | B26: 아군 전체에게 용기 부여 | C26: StatusEffect=Brave, StatusValue, StatusDuration | D26: AllAllies | F26: 아군 전체의 공격력을 StatusValue만큼 증가 | L26: Immortality
A27: HitEnemyProtect | B27: 적 1명에게 단일 피해 + 방어 상승 | C27: BaseValue, ScalingStat, StatusEffect=Protection, StatusValue, StatusDuration | D27: SingleEnemy | E27: HitEnemy + ProtectSelf | F27: 적 1명 공격 후 자신의 방어를 StatusValue만큼 증가 | L27: Dark
A28: ProtectSelf | B28: 자신의 방어 상승 | C28: StatusEffect=Protection, StatusValue, StatusDuration | D28: Self | F28: 자신의 방어를 StatusValue만큼 증가 | L28: Flooding
A29: HitEnemyShield | B29: 적 공격 후 보호막 획득 | C29: BaseValue, ScalingStat, SecondaryValue | D29: SingleEnemy | E29: HitEnemy + ShieldSelf | F29: 적 1명 공격 후 자신의 보호막을 SecondaryValue만큼 획득 | L29: Blindness
A30: StatusLava | B30: 적 1명에게 용암 상태이상 부여 | C30: StatusEffect=Lava, StatusValue, StatusDuration | D30: SingleEnemy | F30: 방어를 StatusValue만큼 하락시키는 용암 디버프를 부여한다. | L30: Contrarywind
A31: StatusLavaAll | B31: 적 전체에게 용암 상태이상 부여 | C31: StatusEffect=Lava, StatusValue, StatusDuration | D31: AllEnemies | F31: 적 전체에게 방어를 StatusValue만큼 하락시키는 용암 디버프를 부여한다. | L31: Spirit
A32: StatusIce | B32: 적 1명에게 얼음 상태이상 부여 | C32: StatusEffect=Ice, StatusValue, StatusDuration | D32: SingleEnemy | F32: 적 1명에의 공격을 StatusValue만큼 하락시키는 얼음 디버프를 부여한다.
A33: StatusIceAll | B33: 적 전체에게 얼음 상태이상 부여 | C33: StatusEffect=Ice, StatusValue, StatusDuration | D33: AllEnemies | F33: 적 전체에게 공격을 StatusValue만큼 하락시키는 얼음 디버프를 부여한다.
A34: ShieldSelfPoisonAll | B34: 자신에게 보호막 생성 + 적 전체에게 중독 부여 | C34: BaseValue, ScalingStat, StatusEffect=Poison, StatusValue, StatusDuration | D34: AllEnemies | E34: ShieldSelf + StatusPoisonAll | F34: 보호막을 획득한 후, StatusValue만큼 중독을 부여한다.
A35: MetalSelf | B35: 자신에게 강철 부여 | C35: StatusEffect=Metal, StatusDuration | D35: Self | F35: 자신에게 한 사이클 동안 받는 데미지를 1로 고정되는 강철 버프를 부여한다.
A36: HitAllEnemiesLavaAll | B36: 적 전체에게 단일 데미지 + 적 전체 용암 디버프 | C36: BaseValue, ScalingStat, StatusEffect=Lava, StatusValue, StatusDuration | D36: AllEnemies | E36: HitAllEnemies + StatusLavaAll | F36: 적 전체에게 BaseValue만큼의 피해를 입히고, StatusVaule만큼 용암을 부여
A37: HitAllEnemiesIceAll | B37: 적 전체에게 단일 데미지 + 적 전체 얼음 디버프 | C37: BaseValue, ScalingStat, StatusEffect=Ice, StatusValue, StatusDuration | D37: AllEnemies | E37: HitAllEnemies + StatusIceAll | F37: 적 전체에게 BaseValue만큼의 피해를 입히고, StatusVaule만큼 얼음을 부여
A38: HitAllEnemiesPoisonAll | B38: 적 전체에게 단일 데미지 + 적 전체 중독 디버프 | C38: BaseValue, ScalingStat, StatusEffect=Poison, StatusValue, StatusDuration | D38: AllEnemies | E38: HitAllEnemies + StatusPoisonAll | F38: 적 전체에게 BaseValue만큼의 피해를 입히고, StatusVaule만큼 중독을 부여
A39: StatusAcid | B39: 적 1명에게 산성 부여 | C39: StatusEffect=Acid, StatusValue, StatusDuration | D39: SingleEnemy | F39: 적 1명에게 산성 부여
A40: StatusAcidAll | B40: 적 전체에게 산성 부여 | C40: StatusEffect=Acid, StatusValue, StatusDuration | D40: AllEnemies | F40: 적 전체에게 산성 부여
A41: HitAllEnemiesAcidAll | B41: 적 전체에게 단일 데미지 + 적 전체 산성 디버프 | C41: BaseValue, ScalingStat, StatusEffect=Acid, StatusValue, StatusDuration | D41: AllEnemies | E41: HitAllEnemies + StatusAcidAll | F41: 적 전체에게 BaseValue만큼의 피해를 입히고, StatusValue만큼 산성을 부여
...

Sheet Enum_State
A1: 버프 및 디버프 Enum 관리
A2: 같은 그룹일 경우 버프 및 디버프 이름이 달라도 같은 효과를 가지며, 중복이 불가능 하다.
A3: 인게임에선 "시스템이름(테마이름)" 이런식으로 출력된다. 둘이 같을 경우 시스템 이름만 출력
B4: GroupId | C4: State Name | D4: 시스템 이름 | E4: 테마 이름 | F4: 종류 | G4: 효과 | H4: TriggerTimer | I4: 비고
B5: State_CostDamage | C5: Reflux | D5: 역류 | E5: 역류 | F5: 디버프 | G5: 에너지를 사용할 때마다 수치만큼 데미지를 받습니다. | I5: 기본 에너지만 적용 | L5: TD | M5: 받는 데미지 | N5: 버프
B6: State_CostUp | C6: Acid | D6: 과욕 | E6: 산성 | F6: 디버프 | G6: 스킬 사용시 에너지 소모량이 1 증가한다. | I6: 기본 에너지만 적용 | L6: FD | M6: 최종 데미지 | N6: 디버프
B7: State_CostUp | C7: Dark | D7: 과욕 | E7: 어둠 | F7: 디버프 | G7: 스킬 사용시 에너지 소모량이 1 증가한다. | H7: OnTakeDamage | I7: 기본 에너지만 적용 | L7: Cost | M7: 에너지 소모
B8: State_Counter | C8: Counter | D8: 반격 | E8: 반격 | F8: 버프 | G8: SecondaryValue만큼의 데미지를 자신을 공격한 대상에게 준다. | H8: OnTakeDamage | I8: 기본 에너지만 적용 | L8: Energy | M8: 기본 에너지
B9: State_EnergyUp | C9: Vitality | D9: 활력 | E9: 활력 | F9: 버프 | G9: 자신의 턴 시작 시 에너지를 수치만큼 추가로 얻는다. | H9: OnTurnStart | I9: 기본 에너지만 적용 | L9: SkillCost | M9: 스킬 에너지 소모
B10: State_Immortality | C10: Immortality | D10: 불사 | E10: 불사 | F10: 버프 | G10: 체력이 1 이하로 내려가지 않습니다. | H10: OnTakeDamage | L10: SkillEnergy | M10: 스킬 에너지
B11: State_Poison | C11: Poison | D11: 중독 | E11: 중독 | F11: 디버프 | G11: 자신의 턴 종료시 수치만큼의 데미지를 받는다. | H11: OnTurnEnd
B12: State_RandomState | C12: Fusion | D12: 퓨전 | E12: 퓨전 | F12: 디버프 | G12: 중독, 용암, 얼음을 랜덤으로 적용시킨다. | I12: 스킬 에너지만 적용
B13: State_SkillCostDamage | C13: InternalInjury | D13: 내상 | E13: 내상 | F13: 디버프 | G13: 스킬 에너지를 사용할 때마다 수치만큼 데미지를 받습니다. | I13: 스킬 에너지만 적용
B14: State_StatDown_ATK | C14: Ice | D14: 허약 | E14: 얼음 | F14: 디버프 | G14: 수치만큼 공격 스텟이 하락한다.
B15: State_StatDown_ATK | C15: Flooding | D15: 허약 | E15: 침수 | F15: 디버프 | G15: 수치만큼 공격 스텟이 하락한다.
B16: State_StatDown_DEF | C16: Lava | D16: 허점 | E16: 용암 | F16: 디버프 | G16: 수치만큼 방어 스텟이 하락한다.
B17: State_StatUp_ATK | C17: Brave | D17: 용기 | E17: 용기 | F17: 버프 | G17: 수치만큼 공격 스텟이 오른다.
B18: State_StatUp_DEF | C18: Protection | D18: 견고 | E18: 가호 | F18: 버프 | G18: 수치만큼 방어 스텟이 오른다.
B19: State_StatUp_DEF | C19: Solid | D19: 견고 | E19: 견고 | F19: 버프 | G19: 수치만큼 방어 스텟이 오른다. | H19: OnTakeDamage
B20: State_StatUp_EVA | C20: Evasion | D20: 민첩 | E20: 민첩 | F20: 버프 | G20: 수치만큼 회피 스텟이 증가한다. | H20: OnTakeDamage
B21: State_TD1 | C21: Indomitable | D21: 불굴 | E21: 불굴 | F21: 버프 | G21: 한 사이클 동안 받는 데미지가 1로 고정된다. | H21: OnTakeDamage
B22: State_TD1 | C22: Metal | D22: 불굴 | E22: 강철 | F22: 버프 | G22: 한 사이클 동안 받는 데미지가 1로 고정된다. | H22: OnTakeDamage | I22: StatusValue가 없다면 BaseValue로 적용
B23: State_TD1 | C23: Spirit | D23: 불굴 | E23: 정령화 | F23: 버프 | G23: 한 사이클 동안 받는 데미지가 1로 고정된다. | H23: OnTakeDamage | I23: StatusValue가 없다면 BaseValue로 적용
B24: State_TD1 | C24: Blindness | D24: 불굴 | E24: 실명 | F24: 버프 | G24: 한 사이클 동안 받는 데미지가 1로 고정된다. | H24: OnTakeDamage
B25: State_FDDown | C25: Fear | D25: 공포 | E25: 공포 | F25: 디버프 | G25: 최종 데미지를 25%만큼 감소시킨다. | H25: OnTakeDamage | I25: StatusValue가 없다면 BaseValue로 적용
B26: State_FDDown | C26: Contrarywind | D26: 공포 | E26: 역풍 | F26: 디버프 | G26: 최종 데미지를 25%만큼 감소시킨다. | H26: None | I26: None
B27: State_TDHeal | C27: Absorption | D27: 흡수 | E27: 흡수 | F27: 버프 | G27: 데미지를 받을 경우 받은 데미지의 StatusValue%만큼 회복합니다. | H27: OnTakeDamage | I27: StatusValue가 없다면 BaseValue로 적용
B28: State_TDUp | C28: Mark | D28: 급소 | E28: 급소 | F28: 디버프 | G28: 받는 데미지가 25% 증가한다. | H28: OnTakeDamage
B29: State_TDDownInt | C29: IronWall | D29: 철벽 | E29: 철벽 | F29: 버프 | G29: 받는 데미지가 StatusValue만큼 줄어든다. | H29: OnTakeDamage | I29: StatusValue가 없다면 BaseValue로 적용
B30: State_SelfDamage | C30: SelfDamage | D30: 반동 피해 | E30: 반동 피해 | F30: 디버프 | G30: 스킬 사용 시 시전자가 수치만큼 반동 피해를 받는다. | H30: OnSkillUsed | I30: SelfDamage 수치만큼 즉시 피해
B31: None | C31: None | D31: None | E31: None | F31: None | G31: None | H31: None | I31: None

Sheet Relic_DataTable
N2: 영구지속: -1 | T2: 계층·효과별 이론적 기준가 (상점 미등장 유물도 가치 산출) | U2: ActionKind 자동 분류 카테고리
A3: RowName | B3: RelicName_KR | C3: RelicDesc_KR | D3: RelicTier | E3: TriggerTiming | F3: ActionKind | G3: TargetType | H3: BaseValue | I3: ScalingStat | J3: ScalingRatio | K3: StatusEffect | L3: OnSkill | M3: StatusValue | N3: StatusDuration | O3: RemainBattle | P3: OwnerClass | Q3: BuyPrice_Dungeon | R3: SellPrice_Dungeon | S3: SellPrice_Gold | T3: Calc_StandardPrice | U3: Effect_Category
A4: RLC_Common_001 | B4: 전사의 증표 | C4: 전투 시작 시 공격 1 증가 | D4: Surface | E4: OnBattleStart | F4: BraveSelf | G4: Self | H4: 0 | J4: 0 | K4: Brave | M4: 1 | N4: -1 | O4: -1 | P4: Shared | Q4: =IF(E4="OnGainRelic", 0, IF(OR(P4="Quest", P4="Monster", P4="Event", D4="Basic", D4="Upgrade"), -1, MIN(IFERROR(VLOOKUP(D4, Relic_Price_Config!$A$5:$E$9, 4, FALSE), 350), MAX(IFERROR(VLOOKUP(D4, Relic_Price_Config!$A$5:$E$9, 3, FALSE), 210), ROUND((IFERROR(VLOOKUP(F4, Relic_Price_Config!$G$5:$N$100, 4, FALSE), 280) + N(H4) * IFERROR(VLOOKUP(F4, Relic_Price_Config!$G$5:$N$100, 5, FALSE), 10) + ABS(N(M4)) * IFERROR(VLOOKUP(F4, Relic_Price_Config!$G$5:$N$100, 6, FALSE), 15) + IF(N(N4)>1, (N(N4)-1)*10, 0)) * IFERROR(VLOOKUP(D4, Relic_Price_Config!$A$5:$E$9, 2, FALSE), 1), 0))))) -> 305 | R4: =IF(OR(E4="OnGainRelic", O4>0), 0, ROUND((IF(Q4>0, Q4, T4)*0.7)/5, 0)*5) -> 215 | S4: =IF(OR(E4="OnGainRelic", O4>0), 0, ROUND((IF(Q4>0, Q4, T4)*1.3)/5, 0)*5) -> 395 | T4: =IF(E4="OnGainRelic", 0, MIN(IFERROR(VLOOKUP(D4, Relic_Price_Config!$A$5:$E$9, 4, FALSE), 350), MAX(IFERROR(VLOOKUP(D4, Relic_Price_Config!$A$5:$E$9, 3, FALSE), 210), ROUND((IFERROR(VLOOKUP(F4, Relic_Price_Config!$G$5:$N$100, 4, FALSE), 280) + N(H4) * IFERROR(VLOOKUP(F4, Relic_Price_Config!$G$5:$N$100, 5, FALSE), 10) + ABS(N(M4)) * IFERROR(VLOOKUP(F4, Relic_Price_Config!$G$5:$N$100, 6, FALSE), 15) + IF(N(N4)>1, (N(N4)-1)*10, 0)) * IFERROR(VLOOKUP(D4, Relic_Price_Config!$A$5:$E$9, 2, FALSE), 1), 0)))) -> 305 | U4: =IF(E4="OnGainRelic", "획득 시 즉발 (0원)", IFERROR(VLOOKUP(F4, Relic_Price_Config!$G$5:$N$100, 2, FALSE), "기타 효과")) -> 공격 증가 [아군 공격 상승]
A5: RLC_Common_002 | B5: 견습 기사의 방패 | C5: 전투 시작 시 방어 1 증가 | D5: Surface | E5: OnBattleStart | F5: ProtectSelf | G5: Self | H5: 0 | J5: 0 | K5: Protection | M5: 1 | N5: -1 | O5: -1 | P5: Shared | Q5: =IF(E5="OnGainRelic", 0, IF(OR(P5="Quest", P5="Monster", P5="Event", D5="Basic", D5="Upgrade"), -1, MIN(IFERROR(VLOOKUP(D5, Relic_Price_Config!$A$5:$E$9, 4, FALSE), 350), MAX(IFERROR(VLOOKUP(D5, Relic_Price_Config!$A$5:$E$9, 3, FALSE), 210), ROUND((IFERROR(VLOOKUP(F5, Relic_Price_Config!$G$5:$N$100, 4, FALSE), 280) + N(H5) * IFERROR(VLOOKUP(F5, Relic_Price_Config!$G$5:$N$100, 5, FALSE), 10) + ABS(N(M5)) * IFERROR(VLOOKUP(F5, Relic_Price_Config!$G$5:$N$100, 6, FALSE), 15) + IF(N(N5)>1, (N(N5)-1)*10, 0)) * IFERROR(VLOOKUP(D5, Relic_Price_Config!$A$5:$E$9, 2, FALSE), 1), 0))))) -> 305 | R5: =IF(OR(E5="OnGainRelic", O5>0), 0, ROUND((IF(Q5>0, Q5, T5)*0.7)/5, 0)*5) -> 215 | S5: =IF(OR(E5="OnGainRelic", O5>0), 0, ROUND((IF(Q5>0, Q5, T5)*1.3)/5, 0)*5) -> 395 | T5: =IF(E5="OnGainRelic", 0, MIN(IFERROR(VLOOKUP(D5, Relic_Price_Config!$A$5:$E$9, 4, FALSE), 350), MAX(IFERROR(VLOOKUP(D5, Relic_Price_Config!$A$5:$E$9, 3, FALSE), 210), ROUND((IFERROR(VLOOKUP(F5, Relic_Price_Config!$G$5:$N$100, 4, FALSE), 280) + N(H5) * IFERROR(VLOOKUP(F5, Relic_Price_Config!$G$5:$N$100, 5, FALSE), 10) + ABS(N(M5)) * IFERROR(VLOOKUP(F5, Relic_Price_Config!$G$5:$N$100, 6, FALSE), 15) + IF(N(N5)>1, (N(N5)-1)*10, 0)) * IFERROR(VLOOKUP(D5, Relic_Price_Config!$A$5:$E$9, 2, FALSE), 1), 0)))) -> 305 | U5: =IF(E5="OnGainRelic", "획득 시 즉발 (0원)", IFERROR(VLOOKUP(F5, Relic_Price_Config!$G$5:$N$100, 2, FALSE), "기타 효과")) -> 방어 증가 [아군 방어 상승]
A6: RLC_Common_003 | B6: 보조 배터리 | C6: 전투 시작 시 에너지 1 추가 | D6: Surface | E6: OnBattleStart | F6: GainEnergy | G6: Self | H6: 1 | J6: 0 | M6: 0 | N6: 0 | O6: -1 | P6: Shared | Q6: =IF(E6="OnGainRelic", 0, IF(OR(P6="Quest", P6="Monster", P6="Event", D6="Basic", D6="Upgrade"), -1, MIN(IFERROR(VLOOKUP(D6, Relic_Price_Config!$A$5:$E$9, 4, FALSE), 350), MAX(IFERROR(VLOOKUP(D6, Relic_Price_Config!$A$5:$E$9, 3, FALSE), 210), ROUND((IFERROR(VLOOKUP(F6, Relic_Price_Config!$G$5:$N$100, 4, FALSE), 280) + N(H6) * IFERROR(VLOOKUP(F6, Relic_Price_Config!$G$5:$N$100, 5, FALSE), 10) + ABS(N(M6)) * IFERROR(VLOOKUP(F6, Relic_Price_Config!$G$5:$N$100, 6, FALSE), 15) + IF(N(N6)>1, (N(N6)-1)*10, 0)) * IFERROR(VLOOKUP(D6, Relic_Price_Config!$A$5:$E$9, 2, FALSE), 1), 0))))) -> 330 | R6: =IF(OR(E6="OnGainRelic", O6>0), 0, ROUND((IF(Q6>0, Q6, T6)*0.7)/5, 0)*5) -> 230 | S6: =IF(OR(E6="OnGainRelic", O6>0), 0, ROUND((IF(Q6>0, Q6, T6)*1.3)/5, 0)*5) -> 430 | T6: =IF(E6="OnGainRelic", 0, MIN(IFERROR(VLOOKUP(D6, Relic_Price_Config!$A$5:$E$9, 4, FALSE), 350), MAX(IFERROR(VLOOKUP(D6, Relic_Price_Config!$A$5:$E$9, 3, FALSE), 210), ROUND((IFERROR(VLOOKUP(F6, Relic_Price_Config!$G$5:$N$100, 4, FALSE), 280) + N(H6) * IFERROR(VLOOKUP(F6, Relic_Price_Config!$G$5:$N$100, 5, FALSE), 10) + ABS(N(M6)) * IFERROR(VLOOKUP(F6, Relic_Price_Config!$G$5:$N$100, 6, FALSE), 15) + IF(N(N6)>1, (N(N6)-1)*10, 0)) * IFERROR(VLOOKUP(D6, Relic_Price_Config!$A$5:$E$9, 2, FALSE), 1), 0)))) -> 330 | U6: =IF(E6="OnGainRelic", "획득 시 즉발 (0원)", IFERROR(VLOOKUP(F6, Relic_Price_Config!$G$5:$N$100, 2, FALSE), "기타 효과")) -> 에너지 관련 (행동력 추가)
A7: RLC_Common_004 | B7: 방어 보조 모듈 | C7: 타격 시 보호막 2 획득 | D7: Surface | E7: OnHitEnemy | F7: ShieldSelf | G7: Self | H7: 2 | J7: 0 | M7: 0 | N7: 0 | O7: -1 | P7: Shared | Q7: =IF(E7="OnGainRelic", 0, IF(OR(P7="Quest", P7="Monster", P7="Event", D7="Basic", D7="Upgrade"), -1, MIN(IFERROR(VLOOKUP(D7, Relic_Price_Config!$A$5:$E$9, 4, FALSE), 350), MAX(IFERROR(VLOOKUP(D7, Relic_Price_Config!$A$5:$E$9, 3, FALSE), 210), ROUND((IFERROR(VLOOKUP(F7, Relic_Price_Config!$G$5:$N$100, 4, FALSE), 280) + N(H7) * IFERROR(VLOOKUP(F7, Relic_Price_Config!$G$5:$N$100, 5, FALSE), 10) + ABS(N(M7)) * IFERROR(VLOOKUP(F7, Relic_Price_Config!$G$5:$N$100, 6, FALSE), 15) + IF(N(N7)>1, (N(N7)-1)*10, 0)) * IFERROR(VLOOKUP(D7, Relic_Price_Config!$A$5:$E$9, 2, FALSE), 1), 0))))) -> 300 | R7: =IF(OR(E7="OnGainRelic", O7>0), 0, ROUND((IF(Q7>0, Q7, T7)*0.7)/5, 0)*5) -> 210 | S7: =IF(OR(E7="OnGainRelic", O7>0), 0, ROUND((IF(Q7>0, Q7, T7)*1.3)/5, 0)*5) -> 390 | T7: =IF(E7="OnGainRelic", 0, MIN(IFERROR(VLOOKUP(D7, Relic_Price_Config!$A$5:$E$9, 4, FALSE), 350), MAX(IFERROR(VLOOKUP(D7, Relic_Price_Config!$A$5:$E$9, 3, FALSE), 210), ROUND((IFERROR(VLOOKUP(F7, Relic_Price_Config!$G$5:$N$100, 4, FALSE), 280) + N(H7) * IFERROR(VLOOKUP(F7, Relic_Price_Config!$G$5:$N$100, 5, FALSE), 10) + ABS(N(M7)) * IFERROR(VLOOKUP(F7, Relic_Price_Config!$G$5:$N$100, 6, FALSE), 15) + IF(N(N7)>1, (N(N7)-1)*10, 0)) * IFERROR(VLOOKUP(D7, Relic_Price_Config!$A$5:$E$9, 2, FALSE), 1), 0)))) -> 300 | U7: =IF(E7="OnGainRelic", "획득 시 즉발 (0원)", IFERROR(VLOOKUP(F7, Relic_Price_Config!$G$5:$N$100, 2, FALSE), "기타 효과")) -> 방어 관련 [보호막 획득]
